Workbook

Sheet BENDROJI
B3: BENDROJI 2022 METŲ BIBLIOTEKŲ ATASKAITA
B5: 1 KULTŪRA METINĖ
R6: Duomenys ataskaitinių metų pabaigoje
O7: Jose: | T7: Bibliotekų, turinčių
M8: Eil. | N8: Biblio- | O8: Dokumentų | P8: Varto- | Q8: Dokumentų | R8: Lanky- | S8: Profesio- | T8: kompiuterius, skaičius
M9: Nr. | N9: tekų | O9: fondas | P9: tojų | Q9: išduotis | R9: tojų | S9: nalūs dar- | U9: iš jų: interne-
N10: skaičius | O10: (fiz. vnt.) | P10: skaičius | Q10: (fiz. vnt.) | R10: skaičius | S10: buotojai | T10: Iš viso | U10: to prieigą
M11: 0 | N11: 1 | O11: 2 | P11: 3 | Q11: 4 | R11: 5 | S11: 6 | T11: 7 | U11: 8
B12: KULTŪROS MINISTERIJA (eil. 2+3+4+5+7+8) | M12: 1 | N12: =SUM(N13,N14,N15,N16,N22,N23) -> 1207 | O12: =SUM(O13,O14,O15,O16,O22,O23) -> 22549694 | P12: =SUM(P13,P14,P15,P16,P22,P23) -> 451905 | Q12: =SUM(Q13,Q14,Q15,Q16,Q22,Q23) -> 11539140 | R12: =SUM(R13,R14,R15,R16,R22,R23) -> 11421409 | S12: =SUM(S13,S14,S15,S16,S22,S23) -> 3054 | T12: =SUM(T13,T14,T15,T16,T22,T23) -> 1205 | U12: =SUM(U13,U14,U15,U16,U22,U23) -> 1205
B13: Lietuvos nacionalinė biblioteka | M13: 2 | N13: 1 | O13: 6471869 | P13: 16312 | Q13: 558526 | R13: 3403376 | S13: 224 | T13: 1 | U13: 1
B14: Lietuvos audiosensorinė (aklųjų) biblioteka | M14: 3 | N14: 1 | O14: 238374 | P14: 7773 | Q14: 100268 | R14: 15753 | S14: 48 | T14: 1 | U14: 1
B15: Apskričių viešosios bibliotekos | M15: 4 | N15: 5 | O15: 3979859 | P15: 40620 | Q15: 961407 | R15: 693520 | S15: 386 | T15: 5 | U15: 5
B16: Savivaldybių viešosios bibliotekos (eil.5a+5b+5c+5d) | M16: 5 | N16: =SUM(N17,N18,N19,N20) -> 1183 | O16: =SUM(O17,O18,O19,O20) -> 11306006 | P16: =SUM(P17,P18,P19,P20) -> 386164 | Q16: =SUM(Q17,Q18,Q19,Q20) -> 9907883 | R16: =SUM(R17,R18,R19,R20) -> 7298602 | S16: =SUM(S17,S18,S19,S20) -> 2379 | T16: =SUM(T17,T18,T19,T20) -> 1183 | U16: =SUM(U17,U18,U19,U20) -> 1183
B17: Viešosios (centrinės) bibliotekos (VB) | M17: 5a | N17: 60 | O17: 3555456 | P17: 173087 | Q17: 3044929 | R17: 2469839 | S17: 1026 | T17: 60 | U17: 60
B18: VB miesto filialai | M18: 5b | N18: 118 | O18: 1987309 | P18: 63037 | Q18: 2695380 | R18: 1820862 | S18: 316 | T18: 118 | U18: 118
B19: VB vaikų filialai | M19: 5c | N19: 9 | O19: 135997 | P19: 9022 | Q19: 233513 | R19: 148880 | S19: 28 | T19: 9 | U19: 9
B20: VB kaimo filialai | M20: 5d | N20: 996 | O20: 5627244 | P20: 141018 | Q20: 3934061 | R20: 2859021 | S20: 1009 | T20: 996 | U20: 996
B21: iš jų VB filialai sujungti su m-lų b-komis | M21: 6 | N21: 45 | O21: 424096 | P21: 8764 | Q21: 242468 | R21: 216694 | S21: 58 | T21: 45 | U21: 45
B22: Muziejų bibliotekos | M22: 7 | N22: 16 | O22: 544510 | P22: 815 | Q22: 4244 | R22: 6332 | S22: 16 | T22: 14 | U22: 14
B23: Kitų kultūros įstaigų bibliotekos | M23: 8 | N23: 1 | O23: 9076 | P23: 221 | Q23: 6812 | R23: 3826 | S23: 1 | T23: 1 | U23: 1
B24: Mokslo įstaigų bibliotekos (eil.9a+9b) | M24: 9 | N24: =SUM(N25:N26) -> 4 | O24: =SUM(O25:O26) -> 4327945 | P24: =SUM(P25:P26) -> 9209 | Q24: =SUM(Q25:Q26) -> 68234 | R24: =SUM(R25:R26) -> 27553 | S24: =SUM(S25:S26) -> 106 | T24: =SUM(T25,T26) -> 4 | U24: =SUM(U25,U26) -> 4
B25: Lietuvos mokslų akademijos Vrublevskių biblioteka | M25: 9a | N25: 1 | O25: 3701827 | P25: 9012 | Q25: 64147 | R25: 26516 | S25: 96 | T25: 1 | U25: 1
B26: Mokslo institutų bibliotekos | M26: 9b | N26: 3 | O26: 626118 | P26: 197 | Q26: 4087 | R26: 1037 | S26: 10 | T26: 3 | U26: 3
B27: Specialiosios bibliotekos (eil.11+12+13+14) | M27: 10 | N27: =SUM(N28,N31,N34,N37) -> 15 | O27: =SUM(O28,O31,O34,O37) -> 1026635 | P27: =SUM(P28,P31,P34,P37) -> 4303 | Q27: =SUM(Q28,Q31,Q34,Q37) -> 60577 | R27: =SUM(R28,R31,R34,R37) -> 21471 | S27: =SUM(S28,S31,S34,S37) -> 38 | T27: =SUM(T28,T31,T34,T37) -> 16 | U27: =SUM(U28,U31,U34,U37) -> 16
B28: Valdžios institucijų bibliotekos. Iš jų: | M28: 11 | N28: =SUM(N29,N30) -> 7 | O28: =SUM(O29,O30) -> 113346 | P28: =SUM(P29,P30) -> 1589 | Q28: =SUM(Q29,Q30) -> 15605 | R28: =SUM(R29,R30) -> 5592 | S28: =SUM(S29,S30) -> 4 | T28: =SUM(T29,T30) -> 7 | U28: =SUM(U29,U30) -> 7
B29: Valdymo institucijų bibliotekos | M29: 11a | N29: 1 | O29: 6127 | P29: 129 | Q29: 711 | R29: 0 | S29: 1 | T29: 1 | U29: 1
B30: Krašto apsaugos ministerijai pavaldžios bibliotekos | M30: 11b | N30: 6 | O30: 107219 | P30: 1460 | Q30: 14894 | R30: 5592 | S30: 3 | T30: 6 | U30: 6
B31: Techninių bibliotekų tinklas (iš viso) | M31: 12 | N31: =SUM(N32,N33) -> 2 | O31: =SUM(O32,O33) -> 19086 | P31: =SUM(P32,P33) -> 438 | Q31: =SUM(Q32,Q33) -> 395 | R31: =SUM(R32,R33) -> 0 | S31: =SUM(S32,S33) -> 1 | T31: =SUM(T32,T33) -> 2 | U31: =SUM(U32,U33) -> 2
M32: 12a
B33: techninės bibliotekos | M33: 12a | N33: 2 | O33: 19086 | P33: 438 | Q33: 395 | R33: 0 | S33: 1 | T33: 2 | U33: 2
B34: Medicinos bibliotekų tinklas (iš viso). Iš jų: | M34: 13 | N34: =SUM(N35,N36) -> 5 | O34: =SUM(O35,O36) -> 597853 | P34: =SUM(P35,P36) -> 2053 | Q34: =SUM(Q35,Q36) -> 44125 | R34: =SUM(R35,R36) -> 15580 | S34: =SUM(S35,S36) -> 31 | T34: =SUM(T35,T36) -> 6 | U34: =SUM(U35,U36) -> 6
B35: Lietuvos medicinos biblioteka | M35: 13a | N35: 1 | O35: 545197 | P35: 832 | Q35: 10669 | R35: 8124 | S35: 25 | T35: 1 | U35: 1
B36: Sveikatos priežiūros įstaigų bibliotekos | M36: 13b | N36: 4 | O36: 52656 | P36: 1221 | Q36: 33456 | R36: 7456 | S36: 6 | T36: 5 | U36: 5
B37: Žemės ūkio bibliotekų tinklas (iš viso) | M37: 14 | N37: 1 | O37: 296350 | P37: 223 | Q37: 452 | R37: 299 | S37: 2 | T37: 1 | U37: 1
B38: Iš viso 2022 m. (eil. 1+10) | M38: 15 | N38: =SUM(N12, N27) -> 1222 | O38: =SUM(O12, O27) -> 23576329 | P38: =SUM(P12, P27) -> 456208 | Q38: =SUM(Q12, Q27) -> 11599717 | R38: =SUM(R12, R27) -> 11442880 | S38: =SUM(S12, S27) -> 3092 | T38: =SUM(T12, T27) -> 1221 | U38: =SUM(U12, U27) -> 1221
B39: Tęsinys kitame lape
O41: Jose: | T41: Bibliotekų, turinčių
N42: Biblio- | O42: Dokumentų | P42: Varto- | Q42: Dokumentų | R42: Lanky- | S42: Profesio- | T42: kompiuterius, skaičius
N43: tekų | O43: fondas | P43: tojų | Q43: išduotis | R43: tojų | S43: nalūs dar- | U43: iš jų su inter-
N44: skaičius | O44: (fiz. vnt.) | P44: skaičius | Q44: (fiz. vnt.) | R44: skaičius | S44: buotojai | T44: Iš viso | U44: neto prieiga
...

Sheet LNB_LAB_AVB
B2: LIETUVOS NACIONALINĖ, LIETUVOS AKLŲJŲ,
B3: APSKRIČIŲ VIEŠOSIOS BIBLIOTEKOS
I4: 2022 METAI
B5: PAGRINDINIAI RODIKLIAI
C7: Bibliotekų skaičius | D7: Dokumentų fondas iš viso (fiz.vnt.) | E7: Vartotojų skaičius | F7: Dokumentų išduotis (fiz.vnt.) | G7: Lankytojų (apsilankymų) skaičius | H7: Profesionalių bibliotekininkų skaičius | I7: Bibliotekų, turinčių kompiuterius, skaičius
I9: iš viso | J9: su interneto prieiga
B11: 1 | C11: 2 | D11: 3 | E11: 4 | F11: 5 | G11: 6 | H11: 7 | I11: 8 | J11: 9
B12: Lietuvos nacionalinė | C12: 1 | D12: 6471869 | E12: 16312 | F12: 558526 | G12: 3403376 | H12: 224 | I12: 1 | J12: 1
B13: 2021 m. | C13: 1 | D13: 6461041 | E13: 13575 | F13: 409834 | G13: 161739 | H13: 217 | I13: 1 | J13: 1
B14: Skirtumas (+, -) | C14: =SUM(C12-C13) -> 0 | D14: =D12-D13 -> 10828 | E14: =E12-E13 -> 2737 | F14: =SUM(F12-F13) -> 148692 | G14: =SUM(G12-G13) -> 3241637 | H14: =SUM(H12-H13) -> 7 | I14: =SUM(I12-I13) -> 0 | J14: =SUM(J12-J13) -> 0
B15: Lietuvos audiosensorinė (aklųjų) | C15: 1 | D15: 238374 | E15: 7773 | F15: 100268 | G15: 15753 | H15: 48 | I15: 1 | J15: 1
B16: 2021 m. | C16: 1 | D16: 242842 | E16: 3910 | F16: 87495 | G16: 14586 | H16: 46 | I16: 1 | J16: 1
B17: Skirtumas (+, -) | C17: =SUM(C15-C16) -> 0 | D17: =SUM(D15-D16) -> -4468 | E17: =SUM(E15-E16) -> 3863 | F17: =SUM(F15-F16) -> 12773 | G17: =SUM(G15-G16) -> 1167 | H17: =SUM(H15-H16) -> 2 | I17: =SUM(I15-I16) -> 0 | J17: =SUM(J15-J16) -> 0
B18: Kauno apskrities viešoji | C18: 1 | D18: 1719759 | E18: 7584 | F18: 214117 | G18: 107788 | H18: 137 | I18: 1 | J18: 1
B19: Klaipėdos apskrities viešoji | C19: 1 | D19: 914140 | E19: 8056 | F19: 173673 | G19: 178624 | H19: 71 | I19: 1 | J19: 1
B20: Panevėžio apskrities viešoji | C20: 1 | D20: 455681 | E20: 6700 | F20: 184538 | G20: 102154 | H20: 72 | I20: 1 | J20: 1
B21: Šiaulių apskrities viešoji | C21: 1 | D21: 482161 | E21: 6056 | F21: 112953 | G21: 93396 | H21: 44 | I21: 1 | J21: 1
B22: Vilniaus apskrities viešoji | C22: 1 | D22: 408118 | E22: 12224 | F22: 276126 | G22: 211558 | H22: 62 | I22: 1 | J22: 1
B23: Iš viso (AVB) | C23: =SUM(C18:C22) -> 5 | D23: =SUM(D18:D22) -> 3979859 | E23: =SUM(E18:E22) -> 40620 | F23: =SUM(F18:F22) -> 961407 | G23: =SUM(G18:G22) -> 693520 | H23: =SUM(H18:H22) -> 386 | I23: =SUM(I18:I22) -> 5 | J23: =SUM(J18:J22) -> 5
B24: 2021 m. | C24: 5 | D24: 4063630 | E24: 39524 | F24: 720566 | G24: 535360 | H24: 391 | I24: 5 | J24: 5
B25: Skirtumas (+, -) | C25: =SUM(C23-C24) -> 0 | D25: =SUM(D23-D24) -> -83771 | E25: =SUM(E23-E24) -> 1096 | F25: =SUM(F23-F24) -> 240841 | G25: =SUM(G23-G24) -> 158160 | H25: =SUM(H23-H24) -> -5 | I25: =SUM(I23-I24) -> 0 | J25: =SUM(J23-J24) -> 0

Sheet SAVIVALDYBIŲ VIEŠOSIOS
C3: SAVIVALDYBIŲ VIEŠOSIOS BIBLIOTEKOS
C5: PAGRINDINIAI RODIKLIAI
C7: 2022 METAI
B9: Apskritys, savivaldybės | C9: Bibliotekų filialų skaičius | D9: Dokumentų fondas iš viso (fiz.vnt.) | E9: Vartotojų skaičius | F9: Dokumentų išduotis (fiz.vnt.) | G9: Lankytojų (apsilankymų) skaičius | H9: Profesionalių bibliotekininkų skaičius | I9: Bibliotekų, turinčių kompiuterius, skaičius
I11: iš viso | J11: su internetu
B12: 1 | C12: 2 | D12: 3 | E12: 4 | F12: 5 | G12: 6 | H12: 7 | I12: 8 | J12: 9
B13: Alytaus apskr.
B14: Alytaus m. | C14: =SUM(VIEŠOSIOS!C13, MIESTŲ_FIL!C13, KAIMO_FIL!C14) -> 4 | D14: =SUM(VIEŠOSIOS!D13, MIESTŲ_FIL!D13, KAIMO_FIL!D14) -> 150194 | E14: =SUM(VIEŠOSIOS!E13, MIESTŲ_FIL!E13, KAIMO_FIL!E14) -> 4600 | F14: =SUM(VIEŠOSIOS!F13, MIESTŲ_FIL!F13, KAIMO_FIL!F14) -> 142145 | G14: =SUM(VIEŠOSIOS!G13, MIESTŲ_FIL!G13, KAIMO_FIL!G14) -> 89497 | H14: =SUM(VIEŠOSIOS!H13, MIESTŲ_FIL!H13, KAIMO_FIL!H14) -> 25 | I14: =SUM(VIEŠOSIOS!I13, MIESTŲ_FIL!I13, KAIMO_FIL!I14) -> 4 | J14: =SUM(VIEŠOSIOS!J13, MIESTŲ_FIL!J13, KAIMO_FIL!J14) -> 4
B15: Alytaus r. | C15: =SUM(VIEŠOSIOS!C14, MIESTŲ_FIL!C14, KAIMO_FIL!C15) -> 34 | D15: =SUM(VIEŠOSIOS!D14, MIESTŲ_FIL!D14, KAIMO_FIL!D15) -> 299628 | E15: =SUM(VIEŠOSIOS!E14, MIESTŲ_FIL!E14, KAIMO_FIL!E15) -> 5284 | F15: =SUM(VIEŠOSIOS!F14, MIESTŲ_FIL!F14, KAIMO_FIL!F15) -> 142282 | G15: =SUM(VIEŠOSIOS!G14, MIESTŲ_FIL!G14, KAIMO_FIL!G15) -> 79122 | H15: =SUM(VIEŠOSIOS!H14, MIESTŲ_FIL!H14, KAIMO_FIL!H15) -> 43 | I15: =SUM(VIEŠOSIOS!I14, MIESTŲ_FIL!I14, KAIMO_FIL!I15) -> 34 | J15: =SUM(VIEŠOSIOS!J14, MIESTŲ_FIL!J14, KAIMO_FIL!J15) -> 34
B16: Druskininkų sav. | C16: =SUM(VIEŠOSIOS!C15, MIESTŲ_FIL!C15, KAIMO_FIL!C16) -> 4 | D16: =SUM(VIEŠOSIOS!D15, MIESTŲ_FIL!D15, KAIMO_FIL!D16) -> 166115 | E16: =SUM(VIEŠOSIOS!E15, MIESTŲ_FIL!E15, KAIMO_FIL!E16) -> 5734 | F16: =SUM(VIEŠOSIOS!F15, MIESTŲ_FIL!F15, KAIMO_FIL!F16) -> 112492 | G16: =SUM(VIEŠOSIOS!G15, MIESTŲ_FIL!G15, KAIMO_FIL!G16) -> 81115 | H16: =SUM(VIEŠOSIOS!H15, MIESTŲ_FIL!H15, KAIMO_FIL!H16) -> 19 | I16: =SUM(VIEŠOSIOS!I15, MIESTŲ_FIL!I15, KAIMO_FIL!I16) -> 4 | J16: =SUM(VIEŠOSIOS!J15, MIESTŲ_FIL!J15, KAIMO_FIL!J16) -> 4
B17: Lazdijų r. | C17: =SUM(VIEŠOSIOS!C16, MIESTŲ_FIL!C16, KAIMO_FIL!C17) -> 22 | D17: =SUM(VIEŠOSIOS!D16, MIESTŲ_FIL!D16, KAIMO_FIL!D17) -> 155891 | E17: =SUM(VIEŠOSIOS!E16, MIESTŲ_FIL!E16, KAIMO_FIL!E17) -> 4736 | F17: =SUM(VIEŠOSIOS!F16, MIESTŲ_FIL!F16, KAIMO_FIL!F17) -> 87473 | G17: =SUM(VIEŠOSIOS!G16, MIESTŲ_FIL!G16, KAIMO_FIL!G17) -> 127982 | H17: =SUM(VIEŠOSIOS!H16, MIESTŲ_FIL!H16, KAIMO_FIL!H17) -> 30 | I17: =SUM(VIEŠOSIOS!I16, MIESTŲ_FIL!I16, KAIMO_FIL!I17) -> 22 | J17: =SUM(VIEŠOSIOS!J16, MIESTŲ_FIL!J16, KAIMO_FIL!J17) -> 22
B18: Varėnos r. | C18: =SUM(VIEŠOSIOS!C17, KAIMO_FIL!C18) -> 20 | D18: =SUM(VIEŠOSIOS!D17, KAIMO_FIL!D18) -> 141992 | E18: =SUM(VIEŠOSIOS!E17, KAIMO_FIL!E18) -> 4250 | F18: =SUM(VIEŠOSIOS!F17, KAIMO_FIL!F18) -> 113636 | G18: =SUM(VIEŠOSIOS!G17, KAIMO_FIL!G18) -> 85780 | H18: =SUM(VIEŠOSIOS!H17, KAIMO_FIL!H18) -> 41 | I18: =SUM(VIEŠOSIOS!I17, KAIMO_FIL!I18) -> 20 | J18: =SUM(VIEŠOSIOS!J17, KAIMO_FIL!J18) -> 20
B19: Iš viso | C19: =SUM(C14:C18) -> 84 | D19: =SUM(D14:D18) -> 913820 | E19: =SUM(E14:E18) -> 24604 | F19: =SUM(F14:F18) -> 598028 | G19: =SUM(G14:G18) -> 463496 | H19: =SUM(H14:H18) -> 158 | I19: =SUM(I14:I18) -> 84 | J19: =SUM(J14:J18) -> 84
B20: Kauno apskr.
B21: Birštono sav. | C21: =SUM(VIEŠOSIOS!C20, MIESTŲ_FIL!C19, KAIMO_FIL!C21) -> 4 | D21: =SUM(VIEŠOSIOS!D20, MIESTŲ_FIL!D19, KAIMO_FIL!D21) -> 72470 | E21: =SUM(VIEŠOSIOS!E20, MIESTŲ_FIL!E19, KAIMO_FIL!E21) -> 1786 | F21: =SUM(VIEŠOSIOS!F20, MIESTŲ_FIL!F19, KAIMO_FIL!F21) -> 34233 | G21: =SUM(VIEŠOSIOS!G20, MIESTŲ_FIL!G19, KAIMO_FIL!G21) -> 30766 | H21: =SUM(VIEŠOSIOS!H20, MIESTŲ_FIL!H19, KAIMO_FIL!H21) -> 13 | I21: =SUM(VIEŠOSIOS!I20, MIESTŲ_FIL!I19, KAIMO_FIL!I21) -> 4 | J21: =SUM(VIEŠOSIOS!J20, MIESTŲ_FIL!J19, KAIMO_FIL!J21) -> 4
B22: Jonavos r. | C22: =SUM(VIEŠOSIOS!C21, MIESTŲ_FIL!C20, KAIMO_FIL!C22) -> 17 | D22: =SUM(VIEŠOSIOS!D21, MIESTŲ_FIL!D20, KAIMO_FIL!D22) -> 169445 | E22: =SUM(VIEŠOSIOS!E21, MIESTŲ_FIL!E20, KAIMO_FIL!E22) -> 9442 | F22: =SUM(VIEŠOSIOS!F21, MIESTŲ_FIL!F20, KAIMO_FIL!F22) -> 223811 | G22: =SUM(VIEŠOSIOS!G21, MIESTŲ_FIL!G20, KAIMO_FIL!G22) -> 127200 | H22: =SUM(VIEŠOSIOS!H21, MIESTŲ_FIL!H20, KAIMO_FIL!H22) -> 39 | I22: =SUM(VIEŠOSIOS!I21, MIESTŲ_FIL!I20, KAIMO_FIL!I22) -> 17 | J22: =SUM(VIEŠOSIOS!J21, MIESTŲ_FIL!J20, KAIMO_FIL!J22) -> 17
B23: Kaišiadorių r. | C23: =SUM(VIEŠOSIOS!C22, MIESTŲ_FIL!C21, KAIMO_FIL!C23) -> 24 | D23: =SUM(VIEŠOSIOS!D22, MIESTŲ_FIL!D21, KAIMO_FIL!D23) -> 165419 | E23: =SUM(VIEŠOSIOS!E22, MIESTŲ_FIL!E21, KAIMO_FIL!E23) -> 5367 | F23: =SUM(VIEŠOSIOS!F22, MIESTŲ_FIL!F21, KAIMO_FIL!F23) -> 80898 | G23: =SUM(VIEŠOSIOS!G22, MIESTŲ_FIL!G21, KAIMO_FIL!G23) -> 69371 | H23: =SUM(VIEŠOSIOS!H22, MIESTŲ_FIL!H21, KAIMO_FIL!H23) -> 38 | I23: =SUM(VIEŠOSIOS!I22, MIESTŲ_FIL!I21, KAIMO_FIL!I23) -> 24 | J23: =SUM(VIEŠOSIOS!J22, MIESTŲ_FIL!J21, KAIMO_FIL!J23) -> 24
B24: Kauno m. | C24: =SUM(VIEŠOSIOS!C23, MIESTŲ_FIL!C22, KAIMO_FIL!C24) -> 19 | D24: =SUM(VIEŠOSIOS!D23, MIESTŲ_FIL!D22, KAIMO_FIL!D24) -> 304908 | E24: =SUM(VIEŠOSIOS!E23, MIESTŲ_FIL!E22, KAIMO_FIL!E24) -> 26286 | F24: =SUM(VIEŠOSIOS!F23, MIESTŲ_FIL!F22, KAIMO_FIL!F24) -> 694357 | G24: =SUM(VIEŠOSIOS!G23, MIESTŲ_FIL!G22, KAIMO_FIL!G24) -> 503467 | H24: =SUM(VIEŠOSIOS!H23, MIESTŲ_FIL!H22, KAIMO_FIL!H24) -> 79 | I24: =SUM(VIEŠOSIOS!I23, MIESTŲ_FIL!I22, KAIMO_FIL!I24) -> 19 | J24: =SUM(VIEŠOSIOS!J23, MIESTŲ_FIL!J22, KAIMO_FIL!J24) -> 19
B25: Kauno r. | C25: =SUM(VIEŠOSIOS!C24, MIESTŲ_FIL!C23, KAIMO_FIL!C25) -> 31 | D25: =SUM(VIEŠOSIOS!D24, MIESTŲ_FIL!D23, KAIMO_FIL!D25) -> 263787 | E25: =SUM(VIEŠOSIOS!E24, MIESTŲ_FIL!E23, KAIMO_FIL!E25) -> 12742 | F25: =SUM(VIEŠOSIOS!F24, MIESTŲ_FIL!F23, KAIMO_FIL!F25) -> 245772 | G25: =SUM(VIEŠOSIOS!G24, MIESTŲ_FIL!G23, KAIMO_FIL!G25) -> 212909 | H25: =SUM(VIEŠOSIOS!H24, MIESTŲ_FIL!H23, KAIMO_FIL!H25) -> 52 | I25: =SUM(VIEŠOSIOS!I24, MIESTŲ_FIL!I23, KAIMO_FIL!I25) -> 31 | J25: =SUM(VIEŠOSIOS!J24, MIESTŲ_FIL!J23, KAIMO_FIL!J25) -> 31
B26: Kėdainių r. | C26: =SUM(VIEŠOSIOS!C25, MIESTŲ_FIL!C24, KAIMO_FIL!C26) -> 40 | D26: =SUM(VIEŠOSIOS!D25, MIESTŲ_FIL!D24, KAIMO_FIL!D26) -> 324187 | E26: =SUM(VIEŠOSIOS!E25, MIESTŲ_FIL!E24, KAIMO_FIL!E26) -> 11353 | F26: =SUM(VIEŠOSIOS!F25, MIESTŲ_FIL!F24, KAIMO_FIL!F26) -> 368562 | G26: =SUM(VIEŠOSIOS!G25, MIESTŲ_FIL!G24, KAIMO_FIL!G26) -> 187164 | H26: =SUM(VIEŠOSIOS!H25, MIESTŲ_FIL!H24, KAIMO_FIL!H26) -> 62 | I26: =SUM(VIEŠOSIOS!I25, MIESTŲ_FIL!I24, KAIMO_FIL!I26) -> 40 | J26: =SUM(VIEŠOSIOS!J25, MIESTŲ_FIL!J24, KAIMO_FIL!J26) -> 40
B27: Prienų r. | C27: =SUM(VIEŠOSIOS!C26, MIESTŲ_FIL!C25, KAIMO_FIL!C27) -> 19 | D27: =SUM(VIEŠOSIOS!D26, MIESTŲ_FIL!D25, KAIMO_FIL!D27) -> 150060 | E27: =SUM(VIEŠOSIOS!E26, MIESTŲ_FIL!E25, KAIMO_FIL!E27) -> 7670 | F27: =SUM(VIEŠOSIOS!F26, MIESTŲ_FIL!F25, KAIMO_FIL!F27) -> 101107 | G27: =SUM(VIEŠOSIOS!G26, MIESTŲ_FIL!G25, KAIMO_FIL!G27) -> 58315 | H27: =SUM(VIEŠOSIOS!H26, MIESTŲ_FIL!H25, KAIMO_FIL!H27) -> 40 | I27: =SUM(VIEŠOSIOS!I26, MIESTŲ_FIL!I25, KAIMO_FIL!I27) -> 19 | J27: =SUM(VIEŠOSIOS!J26, MIESTŲ_FIL!J25, KAIMO_FIL!J27) -> 19
B28: Raseinių r. | C28: =SUM(VIEŠOSIOS!C27, MIESTŲ_FIL!C26, KAIMO_FIL!C28) -> 24 | D28: =SUM(VIEŠOSIOS!D27, MIESTŲ_FIL!D26, KAIMO_FIL!D28) -> 190156 | E28: =SUM(VIEŠOSIOS!E27, MIESTŲ_FIL!E26, KAIMO_FIL!E28) -> 6494 | F28: =SUM(VIEŠOSIOS!F27, MIESTŲ_FIL!F26, KAIMO_FIL!F28) -> 165083 | G28: =SUM(VIEŠOSIOS!G27, MIESTŲ_FIL!G26, KAIMO_FIL!G28) -> 100667 | H28: =SUM(VIEŠOSIOS!H27, MIESTŲ_FIL!H26, KAIMO_FIL!H28) -> 40 | I28: =SUM(VIEŠOSIOS!I27, MIESTŲ_FIL!I26, KAIMO_FIL!I28) -> 24 | J28: =SUM(VIEŠOSIOS!J27, MIESTŲ_FIL!J26, KAIMO_FIL!J28) -> 24
B29: Iš viso | C29: =SUM(C21:C28) -> 178 | D29: =SUM(D21:D28) -> 1640432 | E29: =SUM(E21:E28) -> 81140 | F29: =SUM(F21:F28) -> 1913823 | G29: =SUM(G21:G28) -> 1289859 | H29: =SUM(H21:H28) -> 363 | I29: =SUM(I21:I28) -> 178 | J29: =SUM(J21:J28) -> 178
B30: Klaipėdos apskr.
B31: Klaipėdos m. | C31: =SUM(VIEŠOSIOS!C30, MIESTŲ_FIL!C29, KAIMO_FIL!C31, VAIKŲ_FIL!C15) -> 12 | D31: =SUM(VIEŠOSIOS!D30, MIESTŲ_FIL!D29, KAIMO_FIL!D31, VAIKŲ_FIL!D15) -> 304388 | E31: =SUM(VIEŠOSIOS!E30, MIESTŲ_FIL!E29, KAIMO_FIL!E31, VAIKŲ_FIL!E15) -> 14928 | F31: =SUM(VIEŠOSIOS!F30, MIESTŲ_FIL!F29, KAIMO_FIL!F31, VAIKŲ_FIL!F15) -> 540988 | G31: =SUM(VIEŠOSIOS!G30, MIESTŲ_FIL!G29, KAIMO_FIL!G31, VAIKŲ_FIL!G15) -> 325399 | H31: =SUM(VIEŠOSIOS!H30, MIESTŲ_FIL!H29, KAIMO_FIL!H31, VAIKŲ_FIL!H15) -> 58 | I31: =SUM(VIEŠOSIOS!I30, MIESTŲ_FIL!I29, KAIMO_FIL!I31, VAIKŲ_FIL!I15) -> 12 | J31: =SUM(VIEŠOSIOS!J30, MIESTŲ_FIL!J29, KAIMO_FIL!J31, VAIKŲ_FIL!J15) -> 12
B32: Klaipėdos r. | C32: =SUM(VIEŠOSIOS!C31, MIESTŲ_FIL!C30, KAIMO_FIL!C32) -> 24 | D32: =SUM(VIEŠOSIOS!D31, MIESTŲ_FIL!D30, KAIMO_FIL!D32) -> 227443 | E32: =SUM(VIEŠOSIOS!E31, MIESTŲ_FIL!E30, KAIMO_FIL!E32) -> 10394 | F32: =SUM(VIEŠOSIOS!F31, MIESTŲ_FIL!F30, KAIMO_FIL!F32) -> 211377 | G32: =SUM(VIEŠOSIOS!G31, MIESTŲ_FIL!G30, KAIMO_FIL!G32) -> 160905 | H32: =SUM(VIEŠOSIOS!H31, MIESTŲ_FIL!H30, KAIMO_FIL!H32) -> 47 | I32: =SUM(VIEŠOSIOS!I31, MIESTŲ_FIL!I30, KAIMO_FIL!I32) -> 24 | J32: =SUM(VIEŠOSIOS!J31, MIESTŲ_FIL!J30, KAIMO_FIL!J32) -> 24
B33: Kretingos r. | C33: =SUM(VIEŠOSIOS!C32, MIESTŲ_FIL!C31, KAIMO_FIL!C33) -> 20 | D33: =SUM(VIEŠOSIOS!D32, MIESTŲ_FIL!D31, KAIMO_FIL!D33) -> 208202 | E33: =SUM(VIEŠOSIOS!E32, MIESTŲ_FIL!E31, KAIMO_FIL!E33) -> 5647 | F33: =SUM(VIEŠOSIOS!F32, MIESTŲ_FIL!F31, KAIMO_FIL!F33) -> 143169 | G33: =SUM(VIEŠOSIOS!G32, MIESTŲ_FIL!G31, KAIMO_FIL!G33) -> 185719 | H33: =SUM(VIEŠOSIOS!H32, MIESTŲ_FIL!H31, KAIMO_FIL!H33) -> 42 | I33: =SUM(VIEŠOSIOS!I32, MIESTŲ_FIL!I31, KAIMO_FIL!I33) -> 20 | J33: =SUM(VIEŠOSIOS!J32, MIESTŲ_FIL!J31, KAIMO_FIL!J33) -> 20
B34: Neringos sav. | C34: =SUM(VIEŠOSIOS!C33, MIESTŲ_FIL!C32, KAIMO_FIL!C34) -> 3 | D34: =SUM(VIEŠOSIOS!D33, MIESTŲ_FIL!D32, KAIMO_FIL!D34) -> 89961 | E34: =SUM(VIEŠOSIOS!E33, MIESTŲ_FIL!E32, KAIMO_FIL!E34) -> 1407 | F34: =SUM(VIEŠOSIOS!F33, MIESTŲ_FIL!F32, KAIMO_FIL!F34) -> 19748 | G34: =SUM(VIEŠOSIOS!G33, MIESTŲ_FIL!G32, KAIMO_FIL!G34) -> 16085 | H34: =SUM(VIEŠOSIOS!H33, MIESTŲ_FIL!H32, KAIMO_FIL!H34) -> 9 | I34: =SUM(VIEŠOSIOS!I33, MIESTŲ_FIL!I32, KAIMO_FIL!I34) -> 3 | J34: =SUM(VIEŠOSIOS!J33, MIESTŲ_FIL!J32, KAIMO_FIL!J34) -> 3
B35: Palangos m. sav. | C35: =SUM(VIEŠOSIOS!C34, KAIMO_FIL!C35) -> 1 | D35: =SUM(VIEŠOSIOS!D34, KAIMO_FIL!D35) -> 74051 | E35: =SUM(VIEŠOSIOS!E34, KAIMO_FIL!E35) -> 4968 | F35: =SUM(VIEŠOSIOS!F34, KAIMO_FIL!F35) -> 124450 | G35: =SUM(VIEŠOSIOS!G34, KAIMO_FIL!G35) -> 70282 | H35: =SUM(VIEŠOSIOS!H34, KAIMO_FIL!H35) -> 22 | I35: =SUM(VIEŠOSIOS!I34, KAIMO_FIL!I35) -> 1 | J35: =SUM(VIEŠOSIOS!J34, KAIMO_FIL!J35) -> 1
B36: Skuodo r. | C36: =SUM(VIEŠOSIOS!C35, MIESTŲ_FIL!C33, KAIMO_FIL!C36) -> 15 | D36: =SUM(VIEŠOSIOS!D35, MIESTŲ_FIL!D33, KAIMO_FIL!D36) -> 148686 | E36: =SUM(VIEŠOSIOS!E35, MIESTŲ_FIL!E33, KAIMO_FIL!E36) -> 2197 | F36: =SUM(VIEŠOSIOS!F35, MIESTŲ_FIL!F33, KAIMO_FIL!F36) -> 105581 | G36: =SUM(VIEŠOSIOS!G35, MIESTŲ_FIL!G33, KAIMO_FIL!G36) -> 54478 | H36: =SUM(VIEŠOSIOS!H35, MIESTŲ_FIL!H33, KAIMO_FIL!H36) -> 32 | I36: =SUM(VIEŠOSIOS!I35, MIESTŲ_FIL!I33, KAIMO_FIL!I36) -> 15 | J36: =SUM(VIEŠOSIOS!J35, MIESTŲ_FIL!J33, KAIMO_FIL!J36) -> 15
B37: Šilutės r. | C37: =SUM(VIEŠOSIOS!C36, KAIMO_FIL!C37) -> 22 | D37: =SUM(VIEŠOSIOS!D36, KAIMO_FIL!D37) -> 239468 | E37: =SUM(VIEŠOSIOS!E36, KAIMO_FIL!E37) -> 5902 | F37: =SUM(VIEŠOSIOS!F36, KAIMO_FIL!F37) -> 154130 | G37: =SUM(VIEŠOSIOS!G36, KAIMO_FIL!G37) -> 147341 | H37: =SUM(VIEŠOSIOS!H36, KAIMO_FIL!H37) -> 55 | I37: =SUM(VIEŠOSIOS!I36, KAIMO_FIL!I37) -> 22 | J37: =SUM(VIEŠOSIOS!J36, KAIMO_FIL!J37) -> 22
B38: Iš viso | C38: =SUM(C31:C37) -> 97 | D38: =SUM(D31:D37) -> 1292199 | E38: =SUM(E31:E37) -> 45443 | F38: =SUM(F31:F37) -> 1299443 | G38: =SUM(G31:G37) -> 960209 | H38: =SUM(H31:H37) -> 265 | I38: =SUM(I31:I37) -> 97 | J38: =SUM(J31:J37) -> 97
B39: Marijampolės apskr.
B40: Kalvarijos sav. | C40: =SUM(VIEŠOSIOS!C39, KAIMO_FIL!C40) -> 11 | D40: =SUM(VIEŠOSIOS!D39, KAIMO_FIL!D40) -> 79340 | E40: =SUM(VIEŠOSIOS!E39, KAIMO_FIL!E40) -> 3613 | F40: =SUM(VIEŠOSIOS!F39, KAIMO_FIL!F40) -> 92140 | G40: =SUM(VIEŠOSIOS!G39, KAIMO_FIL!G40) -> 73253 | H40: =SUM(VIEŠOSIOS!H39, KAIMO_FIL!H40) -> 19 | I40: =SUM(VIEŠOSIOS!I39, KAIMO_FIL!I40) -> 11 | J40: =SUM(VIEŠOSIOS!J39, KAIMO_FIL!J40) -> 11
B41: Kazlų Rūdos sav. | C41: =SUM(VIEŠOSIOS!C40, KAIMO_FIL!C41) -> 11 | D41: =SUM(VIEŠOSIOS!D40, KAIMO_FIL!D41) -> 76467 | E41: =SUM(VIEŠOSIOS!E40, KAIMO_FIL!E41) -> 2535 | F41: =SUM(VIEŠOSIOS!F40, KAIMO_FIL!F41) -> 47872 | G41: =SUM(VIEŠOSIOS!G40, KAIMO_FIL!G41) -> 34600 | H41: =SUM(VIEŠOSIOS!H40, KAIMO_FIL!H41) -> 18 | I41: =SUM(VIEŠOSIOS!I40, KAIMO_FIL!I41) -> 11 | J41: =SUM(VIEŠOSIOS!J40, KAIMO_FIL!J41) -> 11
B42: Marijampolės sav. | C42: =SUM(VIEŠOSIOS!C41, MIESTŲ_FIL!C36, KAIMO_FIL!C42) -> 23 | D42: =SUM(VIEŠOSIOS!D41, MIESTŲ_FIL!D36, KAIMO_FIL!D42) -> 178322 | E42: =SUM(VIEŠOSIOS!E41, MIESTŲ_FIL!E36, KAIMO_FIL!E42) -> 8568 | F42: =SUM(VIEŠOSIOS!F41, MIESTŲ_FIL!F36, KAIMO_FIL!F42) -> 192928 | G42: =SUM(VIEŠOSIOS!G41, MIESTŲ_FIL!G36, KAIMO_FIL!G42) -> 164976 | H42: =SUM(VIEŠOSIOS!H41, MIESTŲ_FIL!H36, KAIMO_FIL!H42) -> 45 | I42: =SUM(VIEŠOSIOS!I41, MIESTŲ_FIL!I36, KAIMO_FIL!I42) -> 23 | J42: =SUM(VIEŠOSIOS!J41, MIESTŲ_FIL!J36, KAIMO_FIL!J42) -> 23
B43: Šakių r. | C43: =SUM(VIEŠOSIOS!C42, MIESTŲ_FIL!C37, KAIMO_FIL!C43) -> 18 | D43: =SUM(VIEŠOSIOS!D42, MIESTŲ_FIL!D37, KAIMO_FIL!D43) -> 163590 | E43: =SUM(VIEŠOSIOS!E42, MIESTŲ_FIL!E37, KAIMO_FIL!E43) -> 7860 | F43: =SUM(VIEŠOSIOS!F42, MIESTŲ_FIL!F37, KAIMO_FIL!F43) -> 100752 | G43: =SUM(VIEŠOSIOS!G42, MIESTŲ_FIL!G37, KAIMO_FIL!G43) -> 89046 | H43: =SUM(VIEŠOSIOS!H42, MIESTŲ_FIL!H37, KAIMO_FIL!H43) -> 31 | I43: =SUM(VIEŠOSIOS!I42, MIESTŲ_FIL!I37, KAIMO_FIL!I43) -> 18 | J43: =SUM(VIEŠOSIOS!J42, MIESTŲ_FIL!J37, KAIMO_FIL!J43) -> 18
B44: Vilkaviškio r. | C44: =SUM(VIEŠOSIOS!C43, MIESTŲ_FIL!C38, KAIMO_FIL!C44) -> 26 | D44: =SUM(VIEŠOSIOS!D43, MIESTŲ_FIL!D38, KAIMO_FIL!D44) -> 233580 | E44: =SUM(VIEŠOSIOS!E43, MIESTŲ_FIL!E38, KAIMO_FIL!E44) -> 7298 | F44: =SUM(VIEŠOSIOS!F43, MIESTŲ_FIL!F38, KAIMO_FIL!F44) -> 132975 | G44: =SUM(VIEŠOSIOS!G43, MIESTŲ_FIL!G38, KAIMO_FIL!G44) -> 97290 | H44: =SUM(VIEŠOSIOS!H43, MIESTŲ_FIL!H38, KAIMO_FIL!H44) -> 48 | I44: =SUM(VIEŠOSIOS!I43, MIESTŲ_FIL!I38, KAIMO_FIL!I44) -> 26 | J44: =SUM(VIEŠOSIOS!J43, MIESTŲ_FIL!J38, KAIMO_FIL!J44) -> 26
B45: Iš viso | C45: =SUM(C40:C44) -> 89 | D45: =SUM(D40:D44) -> 731299 | E45: =SUM(E40:E44) -> 29874 | F45: =SUM(F40:F44) -> 566667 | G45: =SUM(G40:G44) -> 459165 | H45: =SUM(H40:H44) -> 161 | I45: =SUM(I40:I44) -> 89 | J45: =SUM(J40:J44) -> 89
B46: Panevėžio apskr.
...

Sheet VIEŠOSIOS
C2: VIEŠOSIOS BIBLIOTEKOS
C4: PAGRINDINIAI RODIKLIAI
I6: 2022 METAI
B8: Apskritys, savivaldybės | C8: Bibliotekų filialų skaičius | D8: Dokumentų fondas iš viso (fiz.vnt.) | E8: Vartotojų skaičius | F8: Dokumentų išduotis (fiz.vnt.) | G8: Lankytojų (apsilankymų) skaičius | H8: Profesionalių bibliotekininkų skaičius | I8: Bibliotekų, turinčių kompiuterius, skaičius
I10: iš viso | J10: su internetu
B11: 1 | C11: 2 | D11: 3 | E11: 4 | F11: 5 | G11: 6 | H11: 7 | I11: 8 | J11: 9
B12: Alytaus apskr.
B13: Alytaus m. | C13: 1 | D13: 90294 | E13: 3312 | F13: 90752 | G13: 58368 | H13: 21 | I13: 1 | J13: 1
B14: Alytaus r. | C14: 1 | D14: 74934 | E14: 1512 | F14: 40729 | G14: 9699 | H14: 7 | I14: 1 | J14: 1
B15: Druskininkų sav. | C15: 1 | D15: 122157 | E15: 4338 | F15: 69046 | G15: 49487 | H15: 14 | I15: 1 | J15: 1
B16: Lazdijų r. | C16: 1 | D16: 51013 | E16: 1238 | F16: 26372 | G16: 51670 | H16: 10 | I16: 1 | J16: 1
B17: Varėnos r. | C17: 1 | D17: 63310 | E17: 2078 | F17: 62307 | G17: 50987 | H17: 22 | I17: 1 | J17: 1
B18: Iš viso | C18: =SUM(C13:C17) -> 5 | D18: =SUM(D13:D17) -> 401708 | E18: =SUM(E13:E17) -> 12478 | F18: =SUM(F13:F17) -> 289206 | G18: =SUM(G12:G17) -> 220211 | H18: =SUM(H12:H17) -> 74 | I18: =SUM(I13:I17) -> 5 | J18: =SUM(J13:J17) -> 5
B19: Kauno apskr.
B20: Birštono sav. | C20: 1 | D20: 59968 | E20: 1221 | F20: 22724 | G20: 23190 | H20: 10 | I20: 1 | J20: 1
B21: Jonavos r. | C21: 1 | D21: 55038 | E21: 4551 | F21: 88688 | G21: 48642 | H21: 18 | I21: 1 | J21: 1
B22: Kaišiadorių r. | C22: 1 | D22: 57218 | E22: 1967 | F22: 27419 | G22: 17815 | H22: 16 | I22: 1 | J22: 1
B23: Kauno m. | C23: 1 | D23: 63922 | E23: 26286 | F23: 99981 | G23: 90777 | H23: 27 | I23: 1 | J23: 1
B24: Kauno r. | C24: 1 | D24: 67363 | E24: 2741 | F24: 59330 | G24: 64042 | H24: 16 | I24: 1 | J24: 1
B25: Kėdainių r. | C25: 1 | D25: 81877 | E25: 2500 | F25: 88660 | G25: 43076 | H25: 21 | I25: 1 | J25: 1
B26: Prienų r. | C26: 1 | D26: 43475 | E26: 4045 | F26: 31860 | G26: 20544 | H26: 19 | I26: 1 | J26: 1
B27: Raseinių r. | C27: 1 | D27: 77204 | E27: 2620 | F27: 69827 | G27: 33448 | H27: 16 | I27: 1 | J27: 1
B28: Iš viso | C28: =SUM(C20:C27) -> 8 | D28: =SUM(D20:D27) -> 506065 | E28: =SUM(E20:E27) -> 45931 | F28: =SUM(F20:F27) -> 488489 | G28: =SUM(G19:G27) -> 341534 | H28: =SUM(H20:H27) -> 143 | I28: =SUM(I20:I27) -> 8 | J28: =SUM(J20:J27) -> 8
B29: Klaipėdos apskr.
B30: Klaipėdos m. | C30: 1 | D30: 94374 | E30: 3548 | F30: 169375 | G30: 96667 | H30: 28 | I30: 1 | J30: 1
B31: Klaipėdos r. | C31: 1 | D31: 57996 | E31: 2880 | F31: 31417 | G31: 34864 | H31: 21 | I31: 1 | J31: 1
B32: Kretingos r. | C32: 1 | D32: 62188 | E32: 3571 | F32: 48357 | G32: 119647 | H32: 20 | I32: 1 | J32: 1
B33: Neringos sav. | C33: 1 | D33: 41045 | E33: 738 | F33: 7386 | G33: 6660 | H33: 6 | I33: 1 | J33: 1
B34: Palangos m. sav. | C34: 1 | D34: 74051 | E34: 4968 | F34: 124450 | G34: 70282 | H34: 22 | I34: 1 | J34: 1
B35: Skuodo r. | C35: 1 | D35: 52592 | E35: 876 | F35: 30647 | G35: 20687 | H35: 16 | I35: 1 | J35: 1
B36: Šilutės r. | C36: 1 | D36: 64346 | E36: 1642 | F36: 39870 | G36: 45671 | H36: 24 | I36: 1 | J36: 1
B37: Iš viso | C37: =SUM(C30:C36) -> 7 | D37: =SUM(D30:D36) -> 446592 | E37: =SUM(E30:E36) -> 18223 | F37: =SUM(F30:F36) -> 451502 | G37: =SUM(G30:G36) -> 394478 | H37: =SUM(H29:H36) -> 137 | I37: =SUM(I30:I36) -> 7 | J37: =SUM(J30:J36) -> 7
B38: Marijampolės apskr.
B39: Kalvarijos sav. | C39: 1 | D39: 24939 | E39: 1776 | F39: 40061 | G39: 40054 | H39: 9 | I39: 1 | J39: 1
B40: Kazlų Rūdos sav. | C40: 1 | D40: 23590 | E40: 839 | F40: 18046 | G40: 14328 | H40: 8 | I40: 1 | J40: 1
B41: Marijampolės sav. | C41: 1 | D41: 56762 | E41: 2850 | F41: 53783 | G41: 66839 | H41: 19 | I41: 1 | J41: 1
B42: Šakių r. | C42: 1 | D42: 54564 | E42: 5450 | F42: 60463 | G42: 54913 | H42: 13 | I42: 1 | J42: 1
B43: Vilkaviškio r. | C43: 1 | D43: 48705 | E43: 1841 | F43: 27645 | G43: 21174 | H43: 20 | I43: 1 | J43: 1
B44: Iš viso | C44: =SUM(C39:C43) -> 5 | D44: =SUM(D39:D43) -> 208560 | E44: =SUM(E39:E43) -> 12756 | F44: =SUM(F39:F43) -> 199998 | G44: =SUM(G38:G43) -> 197308 | H44: =SUM(H38:H43) -> 69 | I44: =SUM(I39:I43) -> 5 | J44: =SUM(J39:J43) -> 5
B45: Panevėžio apskr.
...

Sheet MIESTŲ_FIL
C2: SVB MIESTO FILIALAI
C4: PAGRINDINIAI RODIKLIAI
C6: 2022 METAI
B8: Apskritys, savivaldybės | C8: Bibliotekų filialų skaičius | D8: Dokumentų fondas iš viso (fiz.vnt.) | E8: Vartotojų skaičius | F8: Dokumentų išduotis (fiz.vnt.) | G8: Lankytojų (apsilankymų) skaičius | H8: Profesionalių bibliotekininkų skaičius | I8: Bibliotekų, turinčių kompiuterius, skaičius
I10: iš viso | J10: su internetu
B11: 1 | C11: 2 | D11: 3 | E11: 4 | F11: 5 | G11: 6 | H11: 7 | I11: 8 | J11: 9
B12: Alytaus apskr.
B13: Alytaus m. | C13: 3 | D13: 59900 | E13: 1288 | F13: 51393 | G13: 31129 | H13: 4 | I13: 3 | J13: 3
B14: Alytaus r. | C14: 2 | D14: 42852 | E14: 476 | F14: 11772 | G14: 11119 | H14: 3 | I14: 2 | J14: 2
B15: Druskininkų sav. | C15: 1 | D15: 20251 | E15: 686 | F15: 16312 | G15: 6954 | H15: 1 | I15: 1 | J15: 1
B16: Lazdijų r. | C16: 1 | D16: 13746 | E16: 523 | F16: 11238 | G16: 14422 | H16: 2 | I16: 1 | J16: 1
B17: Iš viso | C17: =SUM(C13:C16) -> 7 | D17: =SUM(D13:D16) -> 136749 | E17: =SUM(E13:E16) -> 2973 | F17: =SUM(F13:F16) -> 90715 | G17: =SUM(G13:G16) -> 63624 | H17: =SUM(H13:H16) -> 10 | I17: =SUM(I13:I16) -> 7 | J17: =SUM(J13:J16) -> 7
B18: Kauno apskr.
B19: Birštono sav. | C19: 1 | D19: 5100 | E19: 299 | F19: 6959 | G19: 5256 | H19: 1 | I19: 1 | J19: 1
B20: Jonavos r. | C20: 1 | D20: 22141 | E20: 1081 | F20: 30545 | G20: 23708 | H20: 4 | I20: 1 | J20: 1
B21: Kaišiadorių r. | C21: 1 | D21: 14349 | E21: 509 | F21: 7494 | G21: 6097 | H21: 2 | I21: 1 | J21: 1
B22: Kauno m. | C22: 18 | D22: 240986 | E22: 0* | F22: 594376 | G22: 412690 | H22: 52 | I22: 18 | J22: 18
B23: Kauno r. | C23: 4 | D23: 32916 | E23: 1262 | F23: 21832 | G23: 22750 | H23: 6 | I23: 4 | J23: 4
B24: Kėdainių r. | C24: 2 | D24: 35613 | E24: 1802 | F24: 90831 | G24: 32127 | H24: 4 | I24: 2 | J24: 2
B25: Prienų r. | C25: 1 | D25: 10296 | E25: 327 | F25: 4382 | G25: 3757 | H25: 2 | I25: 1 | J25: 1
B26: Raseinių r. | C26: 1 | D26: 12771 | E26: 630 | F26: 15909 | G26: 10188 | H26: 2 | I26: 1 | J26: 1
B27: Iš viso | C27: =SUM(C19:C26) -> 29 | D27: =SUM(D19:D26) -> 374172 | E27: =SUM(E19:E26) -> 5910 | F27: =SUM(F19:F26) -> 772328 | G27: =SUM(G19:G26) -> 516573 | H27: =SUM(H19:H26) -> 73 | I27: =SUM(I19:I26) -> 29 | J27: =SUM(J19:J26) -> 29
B28: Klaipėdos apskr.
B29: Klaipėdos m. | C29: 10 | D29: 197512 | E29: 10119 | F29: 349849 | G29: 216808 | H29: 28 | I29: 10 | J29: 10
B30: Klaipėdos r. | C30: 1 | D30: 16909 | E30: 657 | F30: 15967 | G30: 9392 | H30: 2 | I30: 1 | J30: 1
B31: Kretingos r. | C31: 1 | D31: 15780 | E31: 306 | F31: 16568 | G31: 6983 | H31: 2 | I31: 1 | J31: 1
B32: Neringos sav. | C32: 2 | D32: 48916 | E32: 669 | F32: 12362 | G32: 9425 | H32: 3 | I32: 2 | J32: 2
B33: Skuodo r. | C33: 1 | D33: 4379 | E33: 80 | F33: 6269 | G33: 3316 | H33: 1 | I33: 1 | J33: 1
B34: Iš viso | C34: =SUM(C29:C33) -> 15 | D34: =SUM(D29:D33) -> 283496 | E34: =SUM(E29:E33) -> 11831 | F34: =SUM(F29:F33) -> 401015 | G34: =SUM(G29:G33) -> 245924 | H34: =SUM(H29:H33) -> 36 | I34: =SUM(I29:I33) -> 15 | J34: =SUM(J29:J33) -> 15
B35: Marijampolės apskr.
B36: Marijampolės sav. | C36: 1 | D36: 17678 | E36: 1566 | F36: 32673 | G36: 36944 | H36: 4 | I36: 1 | J36: 1
B37: Šakių r. | C37: 2 | D37: 19096 | E37: 799 | F37: 11579 | G37: 6652 | H37: 3 | I37: 2 | J37: 2
B38: Vilkaviškio r. | C38: 2 | D38: 39192 | E38: 1668 | F38: 38499 | G38: 19944 | H38: 5 | I38: 2 | J38: 2
B39: Iš viso | C39: =SUM(C36:C38) -> 5 | D39: =SUM(D36:D38) -> 75966 | E39: =SUM(E36:E38) -> 4033 | F39: =SUM(F36:F38) -> 82751 | G39: =SUM(G36:G38) -> 63540 | H39: =SUM(H36:H38) -> 12 | I39: =SUM(I36:I38) -> 5 | J39: =SUM(J36:J38) -> 5
B40: Panevėžio apskr.
B41: Biržų r. | C41: 1 | D41: 10839 | E41: 208 | F41: 11012 | G41: 6302 | H41: 2 | I41: 1 | J41: 1
B42: Kupiškio r. | C42: 1 | D42: 15065 | E42: 493 | F42: 7508 | G42: 3000 | H42: 2 | I42: 1 | J42: 1
B43: Panevėžio m. | C43: 2 | D43: 32967 | E43: 1610 | F43: 41920 | G43: 22153 | H43: 8 | I43: 2 | J43: 2
B44: Panevėžio r. | C44: 1 | D44: 14503 | E44: 284 | F44: 41620 | G44: 4793 | H44: 2 | I44: 1 | J44: 1
B45: Pasvalio r. | C45: 1 | D45: 14312 | E45: 0* | F45: 17664 | G45: 14735 | H45: 2 | I45: 1 | J45: 1
...

Sheet KAIMO_FIL
C2: SVB KAIMO FILIALAI
C4: PAGRINDINIAI RODIKLIAI
C6: 2022 METAI
B9: Apskritys, savivaldybės | C9: Bibliotekų filialų skaičius | D9: Dokumentų fondas iš viso (fiz.vnt.) | E9: Vartotojų skaičius | F9: Dokumentų išduotis (fiz.vnt.) | G9: Lankytojų (apsilankymų) skaičius | H9: Profesionalių bibliotekininkų skaičius | I9: Bibliotekų, turinčių kompiuterius, skaičius
I11: iš viso | J11: su internetu
B12: 1 | C12: 2 | D12: 3 | E12: 4 | F12: 5 | G12: 6 | H12: 7 | I12: 8 | J12: 9
B13: Alytaus apskr.
B14: Alytaus m. | C14: 0 | D14: 0 | E14: 0 | F14: 0 | G14: 0 | H14: 0 | I14: 0 | J14: 0
B15: Alytaus r. | C15: 31 | D15: 181842 | E15: 3296 | F15: 89781 | G15: 58304 | H15: 33 | I15: 31 | J15: 31
B16: Druskininkų sav. | C16: 2 | D16: 23707 | E16: 710 | F16: 27134 | G16: 24674 | H16: 4 | I16: 2 | J16: 2
B17: Lazdijų r. | C17: 20 | D17: 91132 | E17: 2975 | F17: 49863 | G17: 61890 | H17: 18 | I17: 20 | J17: 20
B18: Varėnos r. | C18: 19 | D18: 78682 | E18: 2172 | F18: 51329 | G18: 34793 | H18: 19 | I18: 19 | J18: 19
B19: Iš viso | C19: =SUM(C14:C18) -> 72 | D19: =SUM(D14:D18) -> 375363 | E19: =SUM(E14:E18) -> 9153 | F19: =SUM(F14:F18) -> 218107 | G19: =SUM(G14:G18) -> 179661 | H19: =SUM(H14:H18) -> 74 | I19: =SUM(I14:I18) -> 72 | J19: =SUM(J14:J18) -> 72
B20: Kauno apskr.
B21: Birštono sav. | C21: 2 | D21: 7402 | E21: 266 | F21: 4550 | G21: 2320 | H21: 2 | I21: 2 | J21: 2
B22: Jonavos r. | C22: 15 | D22: 92266 | E22: 3810 | F22: 104578 | G22: 54850 | H22: 17 | I22: 15 | J22: 15
B23: Kaišiadorių r. | C23: 22 | D23: 93852 | E23: 2891 | F23: 45985 | G23: 45459 | H23: 20 | I23: 22 | J23: 22
B24: Kauno m. | C24: 0 | D24: 0 | E24: 0 | F24: 0 | G24: 0 | H24: 0 | I24: 0 | J24: 0
B25: Kauno r. | C25: 26 | D25: 163508 | E25: 8739 | F25: 164610 | G25: 126117 | H25: 30 | I25: 26 | J25: 26
B26: Kėdainių r. | C26: 37 | D26: 206697 | E26: 7051 | F26: 189071 | G26: 111961 | H26: 37 | I26: 37 | J26: 37
B27: Prienų r. | C27: 17 | D27: 96289 | E27: 3298 | F27: 64865 | G27: 34014 | H27: 19 | I27: 17 | J27: 17
B28: Raseinių r. | C28: 22 | D28: 100181 | E28: 3244 | F28: 79347 | G28: 57031 | H28: 22 | I28: 22 | J28: 22
B29: Iš viso | C29: =SUM(C21:C28) -> 141 | D29: =SUM(D21:D28) -> 760195 | E29: =SUM(E21:E28) -> 29299 | F29: =SUM(F21:F28) -> 653006 | G29: =SUM(G21:G28) -> 431752 | H29: =SUM(H21:H28) -> 147 | I29: =SUM(I21:I28) -> 141 | J29: =SUM(J21:J28) -> 141
B30: Klaipėdos apskr.
B31: Klaipėdos m. | C31: 0 | D31: 0 | E31: 0 | F31: 0 | G31: 0 | H31: 0 | I31: 0 | J31: 0
B32: Klaipėdos r. | C32: 22 | D32: 152538 | E32: 6857 | F32: 163993 | G32: 116649 | H32: 24 | I32: 22 | J32: 22
B33: Kretingos r. | C33: 18 | D33: 130234 | E33: 1770 | F33: 78244 | G33: 59089 | H33: 20 | I33: 18 | J33: 18
B34: Neringos sav. | C34: 0 | D34: 0 | E34: 0 | F34: 0 | G34: 0 | H34: 0 | I34: 0 | J34: 0
B35: Palangos m. sav. | C35: 0 | D35: 0 | E35: 0 | F35: 0 | G35: 0 | H35: 0 | I35: 0 | J35: 0
B36: Skuodo r. | C36: 13 | D36: 91715 | E36: 1241 | F36: 68665 | G36: 30475 | H36: 15 | I36: 13 | J36: 13
B37: Šilutės r. | C37: 21 | D37: 175122 | E37: 4260 | F37: 114260 | G37: 101670 | H37: 31 | I37: 21 | J37: 21
B38: Iš viso | C38: =SUM(C31:C37) -> 74 | D38: =SUM(D31:D37) -> 549609 | E38: =SUM(E31:E37) -> 14128 | F38: =SUM(F31:F37) -> 425162 | G38: =SUM(G31:G37) -> 307883 | H38: =SUM(H31:H37) -> 90 | I38: =SUM(I31:I37) -> 74 | J38: =SUM(J31:J37) -> 74
B39: Marijampolės apskr.
B40: Kalvarijos sav. | C40: 10 | D40: 54401 | E40: 1837 | F40: 52079 | G40: 33199 | H40: 10 | I40: 10 | J40: 10
B41: Kazlų Rūdos sav. | C41: 10 | D41: 52877 | E41: 1696 | F41: 29826 | G41: 20272 | H41: 10 | I41: 10 | J41: 10
B42: Marijampolės sav. | C42: 21 | D42: 103882 | E42: 4152 | F42: 106472 | G42: 61193 | H42: 22 | I42: 21 | J42: 21
B43: Šakių r. | C43: 15 | D43: 89930 | E43: 1611 | F43: 28710 | G43: 27481 | H43: 15 | I43: 15 | J43: 15
B44: Vilkaviškio r. | C44: 23 | D44: 145683 | E44: 3789 | F44: 66831 | G44: 56172 | H44: 23 | I44: 23 | J44: 23
B45: Iš viso | C45: =SUM(C40:C44) -> 79 | D45: =SUM(D40:D44) -> 446773 | E45: =SUM(E40:E44) -> 13085 | F45: =SUM(F40:F44) -> 283918 | G45: =SUM(G40:G44) -> 198317 | H45: =SUM(H40:H44) -> 80 | I45: =SUM(I40:I44) -> 79 | J45: =SUM(J40:J44) -> 79
B46: Panevėžio apskr.
...

Sheet VAIKŲ_FIL
C2: SVB VAIKŲ FILIALAI
C4: PAGRINDINIAI RODIKLIAI
C6: 2022 METAI
B8: Apskritys, savivaldybės | C8: Bibliotekų filialų skaičius | D8: Dokumentų fondas iš viso (fiz.vnt.) | E8: Vartotojų skaičius | F8: Dokumentų išduotis (fiz.vnt.) | G8: Lankytojų (apsilankymų) skaičius | H8: Profesionalių bibliotekininkų skaičius | I8: Bibliotekų, turinčių kompiuterius, skaičius
I10: iš viso | J10: su internetu
B11: 1 | C11: 2 | D11: 3 | E11: 4 | F11: 5 | G11: 6 | H11: 7 | I11: 8 | J11: 9
B12: Alytaus apskr. | C12: 0 | D12: 0 | E12: 0 | F12: 0 | G12: 0 | H12: 0 | I12: 0 | J12: 0
B13: Kauno apskr. | C13: 0 | D13: 0 | E13: 0 | F13: 0 | G13: 0 | H13: 0 | I13: 0 | J13: 0
B14: Klaipėdos apskr.
B15: Klaipėdos m. | C15: 1 | D15: 12502 | E15: 1261 | F15: 21764 | G15: 11924 | H15: 2 | I15: 1 | J15: 1
B16: Marijampolės apskr. | C16: 0 | D16: 0 | E16: 0 | F16: 0 | G16: 0 | H16: 0 | I16: 0 | J16: 0
B17: Panevėžio apskr.
B18: Panevėžio m. | C18: 4 | D18: 54940 | E18: 4457 | F18: 100619 | G18: 62769 | H18: 13 | I18: 4 | J18: 4
B19: Šiaulių apskr.
B20: Šiaulių m. | C20: 2 | D20: 41174 | E20: 1473 | F20: 58061 | G20: 31542 | H20: 6 | I20: 2 | J20: 2
B21: Tauragės apskr. | C21: 0 | D21: 0 | E21: 0 | F21: 0 | G21: 0 | H21: 0 | I21: 0 | J21: 0
B22: Telšių apskr. | C22: 0 | D22: 0 | E22: 0 | F22: 0 | G22: 0 | H22: 0 | I22: 0 | J22: 0
B23: Utenos apskr. | C23: 0 | D23: 0 | E23: 0 | F23: 0 | G23: 0 | H23: 0 | I23: 0 | J23: 0
B24: Vilniaus apskr.
B25: Vilniaus m. | C25: 1 | D25: 15863 | E25: 1399 | F25: 47574 | G25: 39691 | H25: 5 | I25: 1 | J25: 1
B26: Vilniaus raj. | C26: 1 | D26: 11518 | E26: 432 | F26: 5495 | G26: 2954 | H26: 2 | I26: 1 | J26: 1
B27: Iš viso | C27: =SUM(C25:C26) -> 2 | D27: =SUM(D24:D26) -> 27381 | E27: =SUM(E24:E26) -> 1831 | F27: =SUM(F24:F26) -> 53069 | G27: =SUM(G24:G26) -> 42645 | H27: =SUM(H24:H26) -> 7 | I27: =SUM(I24:I26) -> 2 | J27: =SUM(J24:J26) -> 2
B28: Iš viso šalyje | C28: =SUM(C12,C13,C15,C16,C18,C20,C21,C22,C23,C27) -> 9 | D28: =SUM(D12,D13,D15,D16,D18,D20,D21,D22,D23,D27) -> 135997 | E28: =SUM(E12,E13,E15,E16,E18,E20,E21,E22,E23,E27) -> 9022 | F28: =SUM(F12,F13,F15,F16,F18,F20,F21,F22,F23,F27) -> 233513 | G28: =SUM(G12,G13,G15,G16,G18,G20,G21,G22,G23,G27) -> 148880 | H28: =SUM(H12,H13,H15,H16,H18,H20,H21,H22,H23,H27) -> 28 | I28: =SUM(I12,I13,I15,I16,I18,I20,I21,I22,I23,I27) -> 9 | J28: =SUM(J12,J13,J15,J16,J18,J20,J21,J22,J23,J27) -> 9
B29: 2021 m. | C29: 9 | D29: 137832 | E29: 8999 | F29: 204723 | G29: 121431 | H29: 30 | I29: 9 | J29: 9
B30: Skirtumas (+, - ) | C30: =C28-C29 -> 0 | D30: =D28-D29 -> -1835 | E30: =E28-E29 -> 23 | F30: =F28-F29 -> 28790 | G30: =G28-G29 -> 27449 | H30: =H28-H29 -> -2 | I30: =I28-I29 -> 0 | J30: =J28-J29 -> 0

Sheet FILIALAI SU MOKYKLOMIS
C2: SVB KAIMO IR MIESTO FILIALAI
C3: (Veikia kartu su mokyklų bibliotekomis)
C4: PAGRINDINIAI RODIKLIAI
C6: 2022 METAI
B8: Apskritys, savivaldybės | C8: Bibliotekų filialų skaičius | D8: Dokumentų fondas iš viso (fiz.vnt.) | E8: Vartotojų skaičius | F8: Dokumentų išduotis (fiz.vnt.) | G8: Lankytojų (apsilankymų) skaičius | H8: Profesionalių bibliotekininkų skaičius | I8: Bibliotekų, turinčių kompiuterius, skaičius
I10: iš viso | J10: su internetu
B11: 1 | C11: 2 | D11: 3 | E11: 4 | F11: 5 | G11: 6 | H11: 7 | I11: 8 | J11: 9
B12: Alytaus apskr.
B13: Alytaus m. | C13: 0 | D13: 0 | E13: 0 | F13: 0 | G13: 0 | H13: 0 | I13: 0 | J13: 0
B14: Alytaus r. | C14: 7 | D14: 86938 | E14: 1302 | F14: 34318 | G14: 33229 | H14: 10 | I14: 7 | J14: 7
B15: Druskininkų sav. | C15: 0 | D15: 0 | E15: 0 | F15: 0 | G15: 0 | H15: 0 | I15: 0 | J15: 0
B16: Lazdijų r. | C16: 0 | D16: 0 | E16: 0 | F16: 0 | G16: 0 | H16: 0 | I16: 0 | J16: 0
B17: Varėnos r. | C17: 0 | D17: 0 | E17: 0 | F17: 0 | G17: 0 | H17: 0 | I17: 0 | J17: 0
B18: Iš viso | C18: =SUM(C13:C17) -> 7 | D18: =SUM(D13:D17) -> 86938 | E18: =SUM(E13:E17) -> 1302 | F18: =SUM(F13:F17) -> 34318 | G18: =SUM(G13:G17) -> 33229 | H18: =SUM(H13:H17) -> 10 | I18: =SUM(I13:I17) -> 7 | J18: =SUM(J13:J17) -> 7
B19: Kauno apskr.
B20: Birštono sav. | C20: 0 | D20: 0 | E20: 0 | F20: 0 | G20: 0 | H20: 0 | I20: 0 | J20: 0
B21: Jonavos r. | C21: 0 | D21: 0 | E21: 0 | F21: 0 | G21: 0 | H21: 0 | I21: 0 | J21: 0
B22: Kaišiadorių r. | C22: 0 | D22: 0 | E22: 0 | F22: 0 | G22: 0 | H22: 0 | I22: 0 | J22: 0
B23: Kauno m. | C23: 0 | D23: 0 | E23: 0 | F23: 0 | G23: 0 | H23: 0 | I23: 0 | J23: 0
B24: Kauno r. | C24: 0 | D24: 0 | E24: 0 | F24: 0 | G24: 0 | H24: 0 | I24: 0 | J24: 0
B25: Kėdainių r. | C25: 0 | D25: 0 | E25: 0 | F25: 0 | G25: 0 | H25: 0 | I25: 0 | J25: 0
B26: Prienų r. | C26: 0 | D26: 0 | E26: 0 | F26: 0 | G26: 0 | H26: 0 | I26: 0 | J26: 0
B27: Raseinių r. | C27: 0 | D27: 0 | E27: 0 | F27: 0 | G27: 0 | H27: 0 | I27: 0 | J27: 0
B28: Iš viso | C28: =SUM(C20:C27) -> 0 | D28: =SUM(D20:D27) -> 0 | E28: =SUM(E20:E27) -> 0 | F28: =SUM(F20:F27) -> 0 | G28: =SUM(G20:G27) -> 0 | H28: =SUM(H20:H27) -> 0 | I28: =SUM(I20:I27) -> 0 | J28: =SUM(J20:J27) -> 0
B29: Klaipėdos apskr.
B30: Klaipėdos m. | C30: 0 | D30: 0 | E30: 0 | F30: 0 | G30: 0 | H30: 0 | I30: 0 | J30: 0
B31: Klaipėdos r. | C31: 0 | D31: 0 | E31: 0 | F31: 0 | G31: 0 | H31: 0 | I31: 0 | J31: 0
B32: Kretingos r. | C32: 0 | D32: 0 | E32: 0 | F32: 0 | G32: 0 | H32: 0 | I32: 0 | J32: 0
B33: Neringos sav. | C33: 0 | D33: 0 | E33: 0 | F33: 0 | G33: 0 | H33: 0 | I33: 0 | J33: 0
B34: Palangos m. sav. | C34: 0 | D34: 0 | E34: 0 | F34: 0 | G34: 0 | H34: 0 | I34: 0 | J34: 0
B35: Skuodo r. | C35: 0 | D35: 0 | E35: 0 | F35: 0 | G35: 0 | H35: 0 | I35: 0 | J35: 0
B36: Šilutės r. | C36: 9 | D36: 88061 | E36: 2337 | F36: 61831 | G36: 67609 | H36: 16 | I36: 9 | J36: 9
B37: Iš viso | C37: =SUM(C30:C36) -> 9 | D37: =SUM(D30:D36) -> 88061 | E37: =SUM(E30:E36) -> 2337 | F37: =SUM(F30:F36) -> 61831 | G37: =SUM(G30:G36) -> 67609 | H37: =SUM(H30:H36) -> 16 | I37: =SUM(I30:I36) -> 9 | J37: =SUM(J30:J36) -> 9
B38: Marijampolės apskr.
B39: Kalvarijos sav. | C39: 0 | D39: 0 | E39: 0 | F39: 0 | G39: 0 | H39: 0 | I39: 0 | J39: 0
B40: Kazlų Rūdos sav. | C40: 0 | D40: 0 | E40: 0 | F40: 0 | G40: 0 | H40: 0 | I40: 0 | J40: 0
B41: Marijampolės sav. | C41: 1 | D41: 5590 | E41: 179 | F41: 3705 | G41: 2474 | H41: 1 | I41: 1 | J41: 1
B42: Šakių r. | C42: 0 | D42: 0 | E42: 0 | F42: 0 | G42: 0 | H42: 0 | I42: 0 | J42: 0
B43: Vilkaviškio r. | C43: 0 | D43: 0 | E43: 0 | F43: 0 | G43: 0 | H43: 0 | I43: 0 | J43: 0
B44: Iš viso | C44: =SUM(C39:C43) -> 1 | D44: =SUM(D39:D43) -> 5590 | E44: =SUM(E39:E43) -> 179 | F44: =SUM(F39:F43) -> 3705 | G44: =SUM(G39:G43) -> 2474 | H44: =SUM(H39:H43) -> 1 | I44: =SUM(I39:I43) -> 1 | J44: =SUM(J39:J43) -> 1
...

Sheet MUZIEJŲ, KULTŪROS ĮSTAIGŲ
B4: MUZIEJŲ,
B5: KITŲ KULTŪROS ĮSTAIGŲ BIBLIOTEKOS
B8: PAGRINDINIAI RODIKLIAI
H10: 2022 metai
C12: Bibliotekų skaičius | D12: Dokumentų fondas ių viso (fiz.vnt.) | E12: Vartotojų skaičius | F12: Dokumentų išduotis (fiz.vnt.) | G12: Lankytojų (apsilankymų) skaičius | H12: Profesionalių bibliotekininkų skaičius | I12: Bibliotekų, turinčių kompiuterius, skaičius
I14: Iš viso | J14: su internetu
B16: 1 | C16: 2 | D16: 3 | E16: 4 | F16: 5 | G16: 6 | H16: 7 | I16: 8 | J16: 9
B17: Kultūros įstaigų (centrų, archyvų) bibliotekos | C17: 1 | D17: 9076 | E17: 221 | F17: 6812 | G17: 3826 | H17: 1 | I17: 1 | J17: 1
B18: 2021 m. | C18: 1 | D18: 8857 | E18: 230 | F18: 7506 | G18: 3539 | H18: 1 | I18: 1 | J18: 1
B19: Skirtumas (+, -) | C19: =SUM(C17-C18) -> 0 | D19: =SUM(D17-D18) -> 219 | E19: =SUM(E17-E18) -> -9 | F19: =SUM(F17-F18) -> -694 | G19: =SUM(G17-G18) -> 287 | H19: =SUM(H17-H18) -> 0 | I19: =SUM(I17-I18) -> 0 | J19: =SUM(J17-J18) -> 0
B20: Muziejų | C20: 16 | D20: 544510 | E20: 815 | F20: 4244 | G20: 6332 | H20: 16 | I20: 14 | J20: 14
B21: 2021 m. | C21: 16 | D21: 499667 | E21: 728 | F21: 4065 | G21: 4218 | H21: 18 | I21: 14 | J21: 14
B22: Skirtumas (+, -) | C22: =SUM(C20-C21) -> 0 | D22: =SUM(D20-D21) -> 44843 | E22: =SUM(E20-E21) -> 87 | F22: =SUM(F20-F21) -> 179 | G22: =SUM(G20-G21) -> 2114 | H22: =SUM(H20-H21) -> -2 | I22: =SUM(I20-I21) -> 0 | J22: =SUM(J20-J21) -> 0

Sheet LMAB,LMIB
B2: LIETUVOS MOKSLŲ AKADEMIJOS VRUBLEVSKIŲ BIBLIOTEKA
B3: LIETUVOS MOKSLO INSTITUTŲ BIBLIOTEKOS
I5: 2022 METAI
B6: PAGRINDINIAI RODIKLIAI
C8: Bibliotekų skaičius | D8: Dokumentų fondas iš viso (fiz.vnt.) | E8: Vartotojų skaičius | F8: Dokumentų išduotis (fiz.vnt.) | G8: Lankytojų (apsilankymų) skaičius | H8: Profesionalių bibliotekininkų skaičius | I8: Bibliotekų, turinčių kompiuterius, skaičius
I10: iš viso | J10: su internetu
B12: 1 | C12: 2 | D12: 3 | E12: 4 | F12: 5 | G12: 6 | H12: 7 | I12: 8 | J12: 9
B13: Lietuvos mokslų akademijos Vrublevskių biblioteka | C13: 1 | D13: 3701827 | E13: 9012 | F13: 64147 | G13: 26516 | H13: 96 | I13: 1 | J13: 1
B14: 2021 m. | C14: 1 | D14: 3720746 | E14: 9530 | F14: 57684 | G14: 21802 | H14: 96 | I14: 1 | J14: 1
B15: Skirtumas | C15: =SUM(C13-C14) -> 0 | D15: =SUM(D13-D14) -> -18919 | E15: =SUM(E13-E14) -> -518 | F15: =SUM(F13-F14) -> 6463 | G15: =SUM(G13-G14) -> 4714 | H15: =SUM(H13-H14) -> 0 | I15: =SUM(I13-I14) -> 0 | J15: =SUM(J13-J14) -> 0
B16: Lietuvos mokslo institutų | C16: 3 | D16: 626118 | E16: 197 | F16: 4087 | G16: 1037 | H16: 10 | I16: 3 | J16: 3
B17: 2021 m. | C17: 3 | D17: 626091 | E17: 233 | F17: 9443 | G17: 1142 | H17: 9 | I17: 3 | J17: 3
B18: Skirtumas | C18: =SUM(C16-C17) -> 0 | D18: =SUM(D16-D17) -> 27 | E18: =SUM(E16-E17) -> -36 | F18: =SUM(F16-F17) -> -5356 | G18: =SUM(G16-G17) -> -105 | H18: =SUM(H16-H17) -> 1 | I18: =SUM(I16-I17) -> 0 | J18: =SUM(J16-J17) -> 0
B19: Iš viso (LMAVB+LMIB) | C19: =SUM(C13,C16) -> 4 | D19: =SUM(D13,D16) -> 4327945 | E19: =SUM(E13,E16) -> 9209 | F19: =SUM(F13,F16) -> 68234 | G19: =SUM(G13,G16) -> 27553 | H19: =SUM(H13,H16) -> 106 | I19: =SUM(I13,I16) -> 4 | J19: =SUM(J13,J16) -> 4
B20: 2021 m. | C20: 4 | D20: 4346837 | E20: 9763 | F20: 67127 | G20: 22944 | H20: 105 | I20: 4 | J20: 4
B21: Skirtumas | C21: =SUM(C19-C20) -> 0 | D21: =D19-D20 -> -18892 | E21: =E19-E20 -> -554 | F21: =F19-F20 -> 1107 | G21: =G19-G20 -> 4609 | H21: =H19-H20 -> 1 | I21: =I19-I20 -> 0 | J21: =J19-J20 -> 0

Sheet SPECIALIOSIOS
B2: SPECIALIOSIOS BIBLIOTEKOS
I4: 2022 METAI
B5: PAGRINDINIAI RODIKLIAI
C7: Bibliotekų skaičius | D7: Dokumentų fondas iš viso (fiz.vnt.) | E7: Vartotojų skaičius | F7: Dokumentų išduotis (fiz.vnt.) | G7: Lankytojų (apsilankymų) skaičius | H7: Profesionalių bibliotekininkų skaičius | I7: Bibliotekų, turinčių kompiuterius, skaičius
I9: Iš viso | J9: su internetu
B11: 1 | C11: 2 | D11: 3 | E11: 4 | F11: 5 | G11: 6 | H11: 7 | I11: 8 | J11: 9
B12: Krašto apsaugos ministerijai pavaldžios bibliotekos | C12: 6 | D12: 107219 | E12: 1460 | F12: 14894 | G12: 5592 | H12: 3 | I12: 6 | J12: 6
B13: 2021 m. | C13: 6 | D13: 109642 | E13: 1794 | F13: 18001 | G13: 7793 | H13: 5 | I13: 6 | J13: 6
B14: Skirtumas (+, -) | C14: =SUM(C12-C13) -> 0 | D14: =SUM(D12-D13) -> -2423 | E14: =SUM(E12-E13) -> -334 | F14: =SUM(F12-F13) -> -3107 | G14: =SUM(G12-G13) -> -2201 | H14: =SUM(H12-H13) -> -2 | I14: =SUM(I12-I13) -> 0 | J14: =SUM(J12-J13) -> 0
B15: Valdymo institucijų | C15: 1 | D15: 6127 | E15: 129 | F15: 711 | G15: 0 | H15: 1 | I15: 1 | J15: 1
B16: 2021 m. | C16: 1 | D16: 6123 | E16: 134 | F16: 746 | G16: 0 | H16: 1 | I16: 1 | J16: 1
B17: Skirtumas (+, -) | C17: =SUM(C15-C16) -> 0 | D17: =SUM(D15-D16) -> 4 | E17: =SUM(E15-E16) -> -5 | F17: =SUM(F15-F16) -> -35 | G17: =SUM(G15-G16) -> 0 | H17: =SUM(H15-H16) -> 0 | I17: =SUM(I15-I16) -> 0 | J17: =SUM(J15-J16) -> 0
B18: Techninės bibliotekos | C18: 2 | D18: 19086 | E18: 438 | F18: 395 | G18: 0 | H18: 1 | I18: 2 | J18: 2
B19: 2021 m. | C19: 2 | D19: 52306 | E19: 480 | F19: 430 | G19: 1020 | H19: 2 | I19: 2 | J19: 2
B20: Skirtumas (+, -) | C20: =C18-C19 -> 0 | D20: =D18-D19 -> -33220 | E20: =E18-E19 -> -42 | F20: =F18-F19 -> -35 | G20: =G18-G19 -> -1020 | H20: =H18-H19 -> -1 | I20: =I18-I19 -> 0 | J20: =J18-J19 -> 0
B21: Lietuvos medicinos biblioteka | C21: 1 | D21: 545197 | E21: 832 | F21: 10669 | G21: 8124 | H21: 25 | I21: 1 | J21: 1
B22: Sveikatos priežiūros įstaigų | C22: 4 | D22: 52656 | E22: 1221 | F22: 33456 | G22: 7456 | H22: 6 | I22: 5 | J22: 5
B23: Iš viso | C23: =SUM(C21,C22) -> 5 | D23: =SUM(D21,D22) -> 597853 | E23: =SUM(E21,E22) -> 2053 | F23: =SUM(F21,F22) -> 44125 | G23: =SUM(G21,G22) -> 15580 | H23: =SUM(H21,H22) -> 31 | I23: =SUM(I21,I22) -> 6 | J23: =SUM(J21,J22) -> 6
B24: 2021 m. | C24: 6 | D24: 612999 | E24: 2621 | F24: 48967 | G24: 13601 | H24: 31 | I24: 6 | J24: 6
B25: Skirtumas (+, -) | C25: =C23-C24 -> -1 | D25: =SUM(D23-D24) -> -15146 | E25: =E23-E24 -> -568 | F25: =F23-F24 -> -4842 | G25: =G23-G24 -> 1979 | H25: =H23-H24 -> 0 | I25: =I23-I24 -> 0 | J25: =J23-J24 -> 0
B26: Žemės ūkio bibliotekos | C26: 1 | D26: 296350 | E26: 223 | F26: 452 | G26: 299 | H26: 2 | I26: 1 | J26: 1
B27: 2021 m. | C27: 1 | D27: 295872 | E27: 214 | F27: 457 | G27: 299 | H27: 2 | I27: 1 | J27: 1
B28: Skirtumas (+, -) | C28: =C26-C27 -> 0 | D28: =D26-D27 -> 478 | E28: =E26-E27 -> 9 | F28: =F26-F27 -> -5 | G28: =G26-G27 -> 0 | H28: =H26-H27 -> 0 | I28: =I26-I27 -> 0 | J28: =J26-J27 -> 0
B29: Iš viso 2022 m. | C29: =SUM(C12,C15,C18,C23,C26) -> 15 | D29: =SUM(D12,D15,D18,D23,D26) -> 1026635 | E29: =SUM(E12,E15,E18,E23,E26) -> 4303 | F29: =SUM(F12,F15,F18,F23,F26) -> 60577 | G29: =SUM(G12,G15,G18,G23,G26) -> 21471 | H29: =SUM(H12,H15,H18,H23,H26) -> 38 | I29: =SUM(I12,I15,I18,I23,I26) -> 16 | J29: =SUM(J12,J15,J18,J23,J26) -> 16
B30: 2021 m. | C30: 16 | D30: 1076942 | E30: 5243 | F30: 68601 | G30: 22713 | H30: 41 | I30: 16 | J30: 16
B31: Skirtumas (+, -) | C31: =C29-C30 -> -1 | D31: =D29-D30 -> -50307 | E31: =E29-E30 -> -940 | F31: =F29-F30 -> -8024 | G31: =G29-G30 -> -1242 | H31: =H29-H30 -> -3 | I31: =I29-I30 -> 0 | J31: =J29-J30 -> 0

Sheet AMB_VALSTB_NEVALSTB
B2: AUKŠTŲJŲ MOKYKLŲ BIBLIOTEKOS
B3: (Valstybinių, nevalstybinių aukštųjų - universitetinių, kolegijų bibliotekos)
I5: 2022 m.
C7: Bibliotekų skaičius | D7: Jose:
D8: Dokumentų fondas (fiz.vnt.) | E8: Vartotojų skaičius | F8: Dokumentų išduotis (fiz.vnt.) | G8: Lankytojų (apsilankymų) skaičius | H8: Profesionalių bibliotekininkų skaičius | I8: Kompiuterių skaičius vartotojams | J8: Iš jų: su interneto prieiga
B11: 1 | C11: 2 | D11: 3 | E11: 4 | F11: 5 | G11: 6 | H11: 7 | I11: 8 | J11: 9
B12: Valstybiniai universitetai | C12: 11 | D12: 9108777 | E12: 111873 | F12: 666072 | G12: 1448648 | H12: 342 | I12: 1594 | J12: 1584
B13: Valstybinės kolegijos | C13: 12 | D13: 795128 | E13: 26395 | F13: 224691 | G13: 266661 | H13: 59 | I13: 543 | J13: 526
B14: Iš viso | C14: =SUM(C12,C13) -> 23 | D14: =SUM(D12,D13) -> 9903905 | E14: =SUM(E13,E12) -> 138268 | F14: =SUM(F13,F12) -> 890763 | G14: =SUM(G13,G12) -> 1715309 | H14: =SUM(H13,H12) -> 401 | I14: =SUM(I12,I13) -> 2137 | J14: =SUM(J12,J13) -> 2110
B15: 2021 m. | C15: 23 | D15: 10050626 | E15: 139520 | F15: 936708 | G15: 841800 | H15: 419 | I15: 2028 | J15: 1494
B16: Skirtumas (+, -) | C16: 0 | D16: =D14-D15 -> -146721 | E16: =E14-E15 -> -1252 | F16: =F14-F15 -> -45945 | G16: =G14-G15 -> 873509 | H16: =H14-H15 -> -18 | I16: =I14-I15 -> 109 | J16: =J14-J15 -> 616
B17: Nevalstybinės aukštosios | C17: 5 | D17: 171871 | E17: 3855 | F17: 32558 | G17: 31775 | H17: 8 | I17: 65 | J17: 65
B18: Nevalstybinės kolegijos | C18: 6 | D18: 64571 | E18: 3982 | F18: 4796 | G18: 10843 | H18: 9 | I18: 71 | J18: 71
B19: Iš viso | C19: =SUM(C17,C18) -> 11 | D19: =SUM(D17,D18) -> 236442 | E19: =SUM(E17,E18) -> 7837 | F19: =SUM(F17,F18) -> 37354 | G19: =SUM(G17,G18) -> 42618 | H19: =SUM(H17,H18) -> 17 | I19: =SUM(I17,I18) -> 136 | J19: =SUM(J17,J18) -> 136
B20: 2021 m. | C20: 12 | D20: 259300 | E20: 10381 | F20: 34187 | G20: 33208 | H20: 22 | I20: 177 | J20: 130
B21: Skirtumas (+, -) | C21: =C19-C20 -> -1 | D21: =D19-D20 -> -22858 | E21: =E19-E20 -> -2544 | F21: =F19-F20 -> 3167 | G21: =G19-G20 -> 9410 | H21: =H19-H20 -> -5 | I21: =I19-I20 -> -41 | J21: =J19-J20 -> 6
B22: Universitetai (valst.+nevalst.) | C22: =SUM(C12,C17) -> 16 | D22: =SUM(D12,D17) -> 9280648 | E22: =SUM(E12,E17) -> 115728 | F22: =SUM(F12,F17) -> 698630 | G22: =SUM(G12,G17) -> 1480423 | H22: =SUM(H12,H17) -> 350 | I22: =SUM(I12,I17) -> 1659 | J22: =SUM(J12,J17) -> 1649
B23: Kolegijos (valst.+nevalst.) | C23: =SUM(C13,C18) -> 18 | D23: =SUM(D13,D18) -> 859699 | E23: =SUM(E13,E18) -> 30377 | F23: =SUM(F13,F18) -> 229487 | G23: =SUM(G13,G18) -> 277504 | H23: =SUM(H13,H18) -> 68 | I23: =SUM(I13,I18) -> 614 | J23: =SUM(J18,J13) -> 597
B24: Iš viso | C24: =SUM(C22,C23) -> 34 | D24: =SUM(D22,D23) -> 10140347 | E24: =SUM(E22,E23) -> 146105 | F24: =SUM(F22,F23) -> 928117 | G24: =SUM(G22,G23) -> 1757927 | H24: =SUM(H22,H23) -> 418 | I24: =SUM(I22,I23) -> 2273 | J24: =SUM(J22,J23) -> 2246
B25: 2021 m. | C25: 35 | D25: 10309926 | E25: 149901 | F25: 970895 | G25: 875008 | H25: 441 | I25: 2205 | J25: 1624
B26: Skirtumas (+, -) | C26: =C24-C25 -> -1 | D26: =D24-D25 -> -169579 | E26: =E24-E25 -> -3796 | F26: =F24-F25 -> -42778 | G26: =G24-G25 -> 882919 | H26: =H24-H25 -> -23 | I26: =I24-I25 -> 68 | J26: =J24-J25 -> 622

Sheet VALST_AMB_KB
B2: VALSTYBINIŲ AUKŠTŲJŲ (UNIVERSITETINIŲ, KOLEGIJŲ) MOKYKLŲ BIBLIOTEKOS
I5: 2022 m.
B7: Universitetai | C7: Bibliotekų skaičius | D7: Jose:
D8: Dokumentų fondas (fiz.vnt.) | E8: Vartotojų skaičius | F8: Dokumentų išduotis (fiz.vnt.) | G8: Lankytojų (apsilankymų) skaičius | H8: Profesionalių bibliotekininkų skaičius | I8: Kompiuterių skaičius vartotojams | J8: Iš jų: su interneto prieiga
B11: 1 | C11: 2 | D11: 3 | E11: 4 | F11: 5 | G11: 6 | H11: 7 | I11: 8 | J11: 9
B12: Kauno technologijos universitetas | C12: 1 | D12: 868644 | E12: 12013 | F12: 84943 | G12: 166739 | H12: 42 | I12: 197 | J12: 197
B13: Lietuvos sporto universitetas | C13: 1 | D13: 86884 | E13: 2454 | F13: 3995 | G13: 9853 | H13: 9 | I13: 59 | J13: 59
B14: Lietuvos sveikatos mokslų universitetas | C14: 1 | D14: 626154 | E14: 18083 | F14: 182041 | G14: 292119 | H14: 30 | I14: 188 | J14: 182
B15: Vytauto Didžiojo universitetas | C15: 1 | D15: 1025821 | E15: 12029 | F15: 44933 | G15: 105424 | H15: 45 | I15: 262 | J15: 262
B16: Klaipėdos universitetas | C16: 1 | D16: 307602 | E16: 1830 | F16: 29611 | G16: 12868 | H16: 17 | I16: 43 | J16: 43
B17: Generolo Jono Žemaičio Lietuvos karo akademija | C17: 1 | D17: 315090 | E17: 1568 | F17: 13573 | G17: 15703 | H17: 16 | I17: 28 | J17: 27
B18: Lietuvos muzikos ir teatro akademija | C18: 1 | D18: 308749 | E18: 1890 | F18: 11814 | G18: 14666 | H18: 11 | I18: 40 | J18: 40
B19: Mykolo Romerio universitetas | C19: 1 | D19: 190184 | E19: 9697 | F19: 43374 | G19: 61489 | H19: 17 | I19: 93 | J19: 90
B20: Vilniaus dailės akademija | C20: 1 | D20: 109123 | E20: 2730 | F20: 31511 | G20: 15916 | H20: 11 | I20: 26 | J20: 26
B21: Vilniaus Gedimino technikos universitetas | C21: 1 | D21: 375846 | E21: 9771 | F21: 39871 | G21: 112457 | H21: 37 | I21: 48 | J21: 48
B22: Vilniaus universitetas | C22: 1 | D22: 4894680 | E22: 39808 | F22: 180406 | G22: 641414 | H22: 107 | I22: 610 | J22: 610
B23: Iš viso | C23: =SUM(C12:C22) -> 11 | D23: =SUM(D12:D22) -> 9108777 | E23: =SUM(E12:E22) -> 111873 | F23: =SUM(F12:F22) -> 666072 | G23: =SUM(G12:G22) -> 1448648 | H23: =SUM(H12:H22) -> 342 | I23: =SUM(I12:I22) -> 1594 | J23: =SUM(J12:J22) -> 1584
B24: 2021 m. | C24: 11 | D24: 9238143 | E24: 110873 | F24: 647031 | G24: 635222 | H24: 355 | I24: 1559 | J24: 1031
B25: Skirtumas (+, -) | C25: =C23-C24 -> 0 | D25: =D23-D24 -> -129366 | E25: =E23-E24 -> 1000 | F25: =F23-F24 -> 19041 | G25: =G23-G24 -> 813426 | H25: =H23-H24 -> -13 | I25: =I23-I24 -> 35 | J25: =J23-J24 -> 553
B27: Kolegijos | C27: Bibliotekų skaičius | D27: Jose:
D28: Dokumentų fondas (fiz.vnt.) | E28: Vartotojų skaičius | F28: Dokumentų išduotis (fiz.vnt.) | G28: Lankytojų (apsilankymų) skaičius | H28: Profesionalių bibliotekininkų skaičius | I28: Kompiuterių skaičius vartotojams | J28: Iš jų: su interneto prieiga
B31: 1 | C31: 2 | D31: 3 | E31: 4 | F31: 5 | G31: 6 | H31: 7 | I31: 8 | J31: 9
B32: Alytaus kolegija | C32: 1 | D32: 22113 | E32: 1650 | F32: 1553 | G32: 8250 | H32: 2 | I32: 44 | J32: 44
B33: Kauno kolegija | C33: 1 | D33: 86050 | E33: 5118 | F33: 46335 | G33: 88327 | H33: 8 | I33: 67 | J33: 50
B34: Kauno technikos kolegija | C34: 1 | D34: 18935 | E34: 459 | F34: 2618 | G34: 4675 | H34: 2 | I34: 23 | J34: 23
B35: Kauno miškų ir aplinkos inžinerijos kolegija | C35: 1 | D35: 44647 | E35: 204 | F35: 532 | G35: 725 | H35: 1 | I35: 37 | J35: 37
B36: Klaipėdos valstybinė kolegija | C36: 1 | D36: 102901 | E36: 2745 | F36: 26225 | G36: 49654 | H36: 8 | I36: 106 | J36: 106
B37: Lietuvos aukštoji jūreivystės mokykla | C37: 1 | D37: 30344 | E37: 1059 | F37: 7043 | G37: 15000 | H37: 2 | I37: 23 | J37: 23
B38: Marijampolės kolegija | C38: 1 | D38: 24798 | E38: 356 | F38: 4717 | G38: 2873 | H38: 3 | I38: 19 | J38: 19
B39: Panevėžio kolegija | C39: 1 | D39: 59272 | E39: 1199 | F39: 23056 | G39: 19800 | H39: 4 | I39: 36 | J39: 36
B40: Šiaulių valstybinė kolegija | C40: 1 | D40: 49925 | E40: 1886 | F40: 16478 | G40: 13185 | H40: 2 | I40: 37 | J40: 37
B41: Utenos kolegija | C41: 1 | D41: 72360 | E41: 1848 | F41: 2852 | G41: 3348 | H41: 2 | I41: 10 | J41: 10
B42: Vilniaus kolegija | C42: 1 | D42: 139966 | E42: 7763 | F42: 84703 | G42: 40724 | H42: 19 | I42: 85 | J42: 85
B43: Vilniaus technologijų ir dizaino kolegija | C43: 1 | D43: 143817 | E43: 2108 | F43: 8579 | G43: 20100 | H43: 6 | I43: 56 | J43: 56
B44: Iš viso | C44: =SUM(C32:C43) -> 12 | D44: =SUM(D32:D43) -> 795128 | E44: =SUM(E32:E43) -> 26395 | F44: =SUM(F32:F43) -> 224691 | G44: =SUM(G32:G43) -> 266661 | H44: =SUM(H32:H43) -> 59 | I44: =SUM(I32:I43) -> 543 | J44: =SUM(J32:J43) -> 526
B45: 2021 m. | C45: 12 | D45: 812483 | E45: 28647 | F45: 289677 | G45: 206578 | H45: 64 | I45: 469 | J45: 463
B46: Skirtumas (+, -) | C46: =SUM(C44-C45) -> 0 | D46: =D44-D45 -> -17355 | E46: =E44-E45 -> -2252 | F46: =F44-F45 -> -64986 | G46: =G44-G45 -> 60083 | H46: =H44-H45 -> -5 | I46: =I44-I45 -> 74 | J46: =J44-J45 -> 63
B48: Iš viso (aukštųjų, kolegijų) | C48: =SUM(C23+C44) -> 23 | D48: =SUM(D23+D44) -> 9903905 | E48: =SUM(E23+E44) -> 138268 | F48: =SUM(F23+F44) -> 890763 | G48: =SUM(G23+G44) -> 1715309 | H48: =SUM(H23+H44) -> 401 | I48: =SUM(I23,I44) -> 2137 | J48: =SUM(J44,J23) -> 2110
B49: 2021 m. | C49: =SUM(C24+C45) -> 23 | D49: =SUM(D24+D45) -> 10050626 | E49: =SUM(E24+E45) -> 139520 | F49: =SUM(F24+F45) -> 936708 | G49: =SUM(G24+G45) -> 841800 | H49: =SUM(H24+H45) -> 419 | I49: =SUM(I24,I45) -> 2028 | J49: =SUM(J45,J24) -> 1494
B50: Skirtumas (+,-) | C50: =C48-C49 -> 0 | D50: =D48-D49 -> -146721 | E50: =E48-E49 -> -1252 | F50: =F48-F49 -> -45945 | G50: =G48-G49 -> 873509 | H50: =H48-H49 -> -18 | I50: =I48-I49 -> 109 | J50: =J48-J49 -> 616

Sheet VALST_UB
B2: VALSTYBINIŲ UNIVERSITETŲ BIBLIOTEKOS
I4: 2022 m.
C6: Bibliotekų skaičius | D6: Jose:
D7: Dokumentų fondas (fiz.vnt.) | E7: Vartotojų skaičius | F7: Dokumentų išduotis (fiz.vnt.) | G7: Lankytojų (apsilankymų) skaičius | H7: Profesionalių bibliotekininkų skaičius | I7: Kompiuterių skaičius vartotojams | J7: Iš jų: su interneto prieiga
B10: 1 | C10: 2 | D10: 3 | E10: 4 | F10: 5 | G10: 6 | H10: 7 | I10: 8 | J10: 9
B11: Kauno technologijos universitetas | C11: 1 | D11: 868644 | E11: 12013 | F11: 84943 | G11: 166739 | H11: 42 | I11: 197 | J11: 197
B12: Lietuvos sporto universitetas | C12: 1 | D12: 86884 | E12: 2454 | F12: 3995 | G12: 9853 | H12: 9 | I12: 59 | J12: 59
B13: Lietuvos sveikatos mokslų universitetas | C13: 1 | D13: 626154 | E13: 18083 | F13: 182041 | G13: 292119 | H13: 30 | I13: 188 | J13: 182
B14: Vytauto Didžiojo universitetas | C14: 1 | D14: 1025821 | E14: 12029 | F14: 44933 | G14: 105424 | H14: 45 | I14: 262 | J14: 262
B15: Klaipėdos universitetas | C15: 1 | D15: 307602 | E15: 1830 | F15: 29611 | G15: 12868 | H15: 17 | I15: 43 | J15: 43
B16: Generolo Jono Žemaičio Lietuvos karo akademija | C16: 1 | D16: 315090 | E16: 1568 | F16: 13573 | G16: 15703 | H16: 16 | I16: 28 | J16: 27
B17: Lietuvos muzikos ir teatro akademija | C17: 1 | D17: 308749 | E17: 1890 | F17: 11814 | G17: 14666 | H17: 11 | I17: 40 | J17: 40
